<?xml version="1.0" ?>
<!-- =================================================================================== -->
<!-- |    This document was autogenerated by xacro from /home/adela/catkin_ws/src/tori/tori_description/urdf/tori_robot.urdf.xacro | -->
<!-- |    EDITING THIS FILE BY HAND IS NOT RECOMMENDED                                 | -->
<!-- =================================================================================== -->
<robot name="tori">
  <gazebo>
    <plugin filename="libgazebo_ros_control.so" name="ros_control">
      <!--robotNamespace>/</robotNamespace-->
      <!--robotSimType>gazebo_ros_control/DefaultRobotHWSim</robotSimType-->
    </plugin>
    <!--
    <plugin name="gazebo_ros_power_monitor_controller" filename="libgazebo_ros_power_monitor.so">
      <alwaysOn>true</alwaysOn>
      <updateRate>1.0</updateRate>
      <timeout>5</timeout>
      <powerStateTopic>power_state</powerStateTopic>
      <powerStateRate>10.0</powerStateRate>
      <fullChargeCapacity>87.78</fullChargeCapacity>     
      <dischargeRate>-474</dischargeRate>
      <chargeRate>525</chargeRate>
      <dischargeVoltage>15.52</dischargeVoltage>
      <chargeVoltage>16.41</chargeVoltage>
    </plugin>
-->
  </gazebo>
  <plugin filename="libRealSensePlugin.so" name="rs"/>
  <!-- camera_l -->
  <!--
  <gazebo reference="camera_l_link">
    <sensor type="camera" name="camera_l">
      <update_rate>3.0</update_rate>
      <camera name="cam_l">
        <horizontal_fov>1.3962634</horizontal_fov>
        <image>
          <width>800</width>
          <height>800</height>
          <format>R8G8B8</format>
        </image>
        <clip>
          <near>0.02</near>
          <far>300</far>
        </clip>
        <noise>
          <type>gaussian</type>

          <mean>0.0</mean>
          <stddev>0.007</stddev>
        </noise>
      </camera>
      <plugin name="camera_controller" filename="libgazebo_ros_camera.so">
        <alwaysOn>true</alwaysOn>
        <updateRate>0.0</updateRate>
        <cameraName>camera_l</cameraName>
        <imageTopicName>image_raw</imageTopicName>
        <cameraInfoTopicName>camera_info</cameraInfoTopicName>
        <frameName>camera_l_link</frameName>
        <hackBaseline>0.07</hackBaseline>
        <distortionK1>0.0</distortionK1>
        <distortionK2>0.0</distortionK2>
        <distortionK3>0.0</distortionK3>
        <distortionT1>0.0</distortionT1>
        <distortionT2>0.0</distortionT2>
      </plugin>
    </sensor>
  </gazebo>



  <gazebo reference="camera_r_link">
    <sensor type="camera" name="camera_r">
      <update_rate>3.0</update_rate>
      <camera name="cam_r">
        <horizontal_fov>1.3962634</horizontal_fov>
        <image>
          <width>800</width>
          <height>800</height>
          <format>R8G8B8</format>
        </image>
        <clip>
          <near>0.02</near>
          <far>300</far>
        </clip>
        <noise>
          <type>gaussian</type>

          <mean>0.0</mean>
          <stddev>0.007</stddev>
        </noise>
      </camera>
      <plugin name="camera_controller" filename="libgazebo_ros_camera.so">
        <alwaysOn>true</alwaysOn>
        <updateRate>0.0</updateRate>
        <cameraName>camera_r</cameraName>
        <imageTopicName>image_raw</imageTopicName>
        <cameraInfoTopicName>camera_info</cameraInfoTopicName>
        <frameName>camera_r_link</frameName>
        <hackBaseline>0.07</hackBaseline>
        <distortionK1>0.0</distortionK1>
        <distortionK2>0.0</distortionK2>
        <distortionK3>0.0</distortionK3>
        <distortionT1>0.0</distortionT1>
        <distortionT2>0.0</distortionT2>
      </plugin>
    </sensor>
  </gazebo>-->
  <!--
  <plugin name="camera_plugin" filename="libgazebo_ros_openni_kinect.so">
    <baseline>0.2</baseline>
    <alwaysOn>true</alwaysOn>

    <updateRate>0.0</updateRate>
    <cameraName>camera_ir</cameraName>
    <imageTopicName>/camera/color/image_raw</imageTopicName>
    <cameraInfoTopicName>/camera/color/camera_info</cameraInfoTopicName>
    <depthImageTopicName>/camera/depth/image_raw</depthImageTopicName>
    <depthImageCameraInfoTopicName>/camera/depth/camera_info</depthImageCameraInfoTopicName>
    <pointCloudTopicName>/camera/depth/points</pointCloudTopicName>
    <frameName>camera_l_link</frameName>
    <pointCloudCutoff>0.5</pointCloudCutoff>
    <pointCloudCutoffMax>3.0</pointCloudCutoffMax>
    <distortionK1>0</distortionK1>
    <distortionK2>0</distortionK2>
    <distortionK3>0</distortionK3>
    <distortionT1>0</distortionT1>
    <distortionT2>0</distortionT2>
    <CxPrime>0</CxPrime>
    <Cx>0</Cx>
    <Cy>0</Cy>
    <focalLength>0</focalLength>
    <hackBaseline>0</hackBaseline>
  </plugin>
-->
  <!-- stereo plugin that produces a raw_stereo message
  -->
  <!--
  <map name="sensor" flag="gazebo">
    <verbatim key="camera_controller">
      <controller:ros_stereo_camera name="camera_controller" plugin="libros_stereo_camera.so">
        <alwaysOn>true</alwaysOn>
        <updateRate>20.0</updateRate>
        <leftCamera>camera_l_link</leftCamera>
        <rightCamera>camera_r_link</rightCamera>
        <topicName>${name}/raw_stereo</topicName>
        <frameName>${name}_optical_frame</frameName>
        <CxPrime>320</CxPrime>
        <Cx>320</Cx>
        <Cy>240</Cy>
        <focal_length>320</focal_length> -->
  <!-- image_width / (2*tan(hfov_radian /2)) -->
  <!--<distortion_k1>0</distortion_k1>
        <distortion_k2>0</distortion_k2>
        <distortion_k3>0</distortion_k3>
        <distortion_t1>0</distortion_t1>
        <distortion_t2>0</distortion_t2>
        <baseline>${stereo_dy}</baseline>-->
  <!-- home pos. of robot has +x forward, +y left -->
  <!--<interface:stereocamera name="${name}_iface" />
      </controller:ros_stereo_camera>
    </verbatim>
  </map>-->
  <!-- Probably needed!<xacro:include filename="$(find tori_description)/urdf/realsense_camera/model.sdf" />-->
  <!--NEEDED! <xacro:include filename="$(find realsense2_description)/urdf/_d415.urdf.xacro"/>-->
  <!--<xacro:macro name="rs_cam_stuff" params="parent">
    <link name="cam_link">
      <gazebo reference="sensor_d415_link"/>
    </link>
    <joint name="cam_joint" type="fixed">
      <parent link="${parent}"/>
      <child link="sensor_d415_link"/>
      <origin xyz="0 0 1.5"/>
    </joint>
  </xacro:macro>-->
  <!--<xacro:macro name="rs_model_stuff" params="">
    <link name="rs_model_link">
      <gazebo reference="realsense_camera"/>
    </link>
    <joint name="rs_model_joint">
      <parent link="torso_upper"/>
      <child link="rs_model_link"/>
      <origin xyz="0 0 1.5"/>
    </joint>
  </xacro:macro>-->
  <!--<gazebo reference="torso_upper"> this -->
  <!--<sensor type="depth" name="camera1">-->
  <!--<plugin name="gazebo_realsense" filename="libRealSensePlugin.so">
        <robotNamespace>/</robotNamespace>
      </plugin>-->
  <!-- from here<plugin name="realsense_gazebo_plugin" filename="realsense_gazebo_plugin.so">
        <robotNamespace>/</robotNamespace>
      </plugin> to here-->
  <!--</sensor>-->
  <!--</gazebo> this-->
  <!-- -.18 -->
  <!--.1-->
  <!-- ~7.0V-->
  <!--<link name="world"/>
     <joint name="world_joint" type="fixed">
       <parent link="world"/>
       <child link="dummy"/>
     </joint>-->
  <link name="dummy">
   </link>
  <link name="pelvis">
    <!-- formerly base_link-->
    <visual>
      <origin rpy="0 0 0" xyz="0 0 0"/>
      <geometry>
        <mesh filename="package://tori_description/meshes/pelvis.stl" scale=".001 .001 .001"/>
      </geometry>
      <material name="LightGrey">
        <color rgba="0.7 0.7 0.7 1.0"/>
      </material>
    </visual>
    <collision>
      <origin rpy="0 0 0" xyz="0 0 0"/>
      <geometry>
        <mesh filename="package://tori_description/meshes/pelvis.stl" scale=".001 .001 .001"/>
        --&gt;
        
      </geometry>
    </collision>
    <inertial>
      <origin rpy="0 0 0" xyz="-.000062107 -.002467480 .000540235"/>
      <mass value="0.186"/>
      <inertia ixx="0.000231550208" ixy="3.199811875e-07" ixz="-3.6778775e-07" iyy="0.000993170496" iyz="2.7907164e-05" izz="0.000822"/>
    </inertial>
  </link>
  <joint name="hip_r_z_servo_0_joint" type="fixed">
    <parent link="pelvis"/>
    <child link="hip_r_z_servo_0"/>
    <origin rpy="0 0 1.5707963267948966" xyz="-.091 0 -.027"/>
  </joint>
  <link name="hip_r_z_servo_0">
    <visual>
      <origin rpy="0 0 0" xyz="0 0 0"/>
      <geometry>
        <mesh filename="package://tori_description/meshes/servo.stl" scale=".001 .001 .001"/>
      </geometry>
      <material name="Black"/>
      <color rgba="0.0 0.0 0.0 0.0"/>
    </visual>
    <collision>
      <origin rpy="0 0 0" xyz="0 0 0"/>
      <geometry>
        <mesh filename="package://tori_description/meshes/servo.stl" scale=".001 .001 .001"/>
        --&gt;
        
      </geometry>
    </collision>
    <inertial>
      <origin rpy="0 0 0" xyz="0 0 0"/>
      <mass value="0.07"/>
      <inertia ixx="8.106666e-06" ixy="0.0" ixz="0.0" iyy="4.967866e-06" iyz="0.0" izz="4.967866e-06"/>
    </inertial>
  </link>
  <joint name="hip_r_z_servo_1_joint" type="fixed">
    <!--TODO: Technically wrong leg, but it shouldn't actually matter (also check other hip_z servos)-->
    <parent link="pelvis"/>
    <child link="hip_r_z_servo_1"/>
    <origin rpy="0 0 1.5707963267948966" xyz=".091 0 -.027"/>
  </joint>
  <link name="hip_r_z_servo_1">
    <visual>
      <origin rpy="0 0 0" xyz="0 0 0"/>
      <geometry>
        <mesh filename="package://tori_description/meshes/servo.stl" scale=".001 .001 .001"/>
      </geometry>
      <material name="Black"/>
      <color rgba="0.0 0.0 0.0 0.0"/>
    </visual>
    <collision>
      <origin rpy="0 0 0" xyz="0 0 0"/>
      <geometry>
        <mesh filename="package://tori_description/meshes/servo.stl" scale=".001 .001 .001"/>
        --&gt;
        
      </geometry>
    </collision>
    <inertial>
      <origin rpy="0 0 0" xyz="0 0 0"/>
      <mass value="0.07"/>
      <inertia ixx="8.106666e-06" ixy="0.0" ixz="0.0" iyy="4.967866e-06" iyz="0.0" izz="4.967866e-06"/>
    </inertial>
  </link>
  <joint name="hip_l_z_servo_0_joint" type="fixed">
    <parent link="pelvis"/>
    <child link="hip_l_z_servo_0"/>
    <origin rpy="0 0 1.5707963267948966" xyz="-.091 0 .018"/>
  </joint>
  <link name="hip_l_z_servo_0">
    <visual>
      <origin rpy="0 0 0" xyz="0 0 0"/>
      <geometry>
        <mesh filename="package://tori_description/meshes/servo.stl" scale=".001 .001 .001"/>
      </geometry>
      <material name="Black"/>
      <color rgba="0.0 0.0 0.0 0.0"/>
    </visual>
    <collision>
      <origin rpy="0 0 0" xyz="0 0 0"/>
      <geometry>
        <mesh filename="package://tori_description/meshes/servo.stl" scale=".001 .001 .001"/>
        --&gt;
        
      </geometry>
    </collision>
    <inertial>
      <origin rpy="0 0 0" xyz="0 0 0"/>
      <mass value="0.07"/>
      <inertia ixx="8.106666e-06" ixy="0.0" ixz="0.0" iyy="4.967866e-06" iyz="0.0" izz="4.967866e-06"/>
    </inertial>
  </link>
  <joint name="hip_l_z_servo_1_joint" type="fixed">
    <parent link="pelvis"/>
    <child link="hip_l_z_servo_1"/>
    <origin rpy="0 0 1.5707963267948966" xyz=".091 0 .018"/>
  </joint>
  <link name="hip_l_z_servo_1">
    <visual>
      <origin rpy="0 0 0" xyz="0 0 0"/>
      <geometry>
        <mesh filename="package://tori_description/meshes/servo.stl" scale=".001 .001 .001"/>
      </geometry>
      <material name="Black"/>
      <color rgba="0.0 0.0 0.0 0.0"/>
    </visual>
    <collision>
      <origin rpy="0 0 0" xyz="0 0 0"/>
      <geometry>
        <mesh filename="package://tori_description/meshes/servo.stl" scale=".001 .001 .001"/>
        --&gt;
        
      </geometry>
    </collision>
    <inertial>
      <origin rpy="0 0 0" xyz="0 0 0"/>
      <mass value="0.07"/>
      <inertia ixx="8.106666e-06" ixy="0.0" ixz="0.0" iyy="4.967866e-06" iyz="0.0" izz="4.967866e-06"/>
    </inertial>
  </link>
  <joint name="spine_x_servo_0_joint" type="fixed">
    <parent link="pelvis"/>
    <child link="spine_x_servo_0"/>
    <origin rpy="0 0 1.5707963267948966" xyz="-.023 0 .053"/>
  </joint>
  <link name="spine_x_servo_0">
    <visual>
      <origin rpy="0 0 0" xyz="0 0 0"/>
      <geometry>
        <mesh filename="package://tori_description/meshes/servo.stl" scale=".001 .001 .001"/>
      </geometry>
      <material name="Black"/>
      <color rgba="0.0 0.0 0.0 0.0"/>
    </visual>
    <collision>
      <origin rpy="0 0 0" xyz="0 0 0"/>
      <geometry>
        <mesh filename="package://tori_description/meshes/servo.stl" scale=".001 .001 .001"/>
        --&gt;
        
      </geometry>
    </collision>
    <inertial>
      <origin rpy="0 0 0" xyz="0 0 0"/>
      <mass value="0.068"/>
      <inertia ixx="8.106666e-06" ixy="0.0" ixz="0.0" iyy="4.967866e-06" iyz="0.0" izz="4.967866e-06"/>
    </inertial>
  </link>
  <joint name="spine_x_servo_1_joint" type="fixed">
    <parent link="pelvis"/>
    <child link="spine_x_servo_1"/>
    <origin rpy="0 0 1.5707963267948966" xyz=".023 0 .053"/>
  </joint>
  <link name="spine_x_servo_1">
    <collision>
      <origin rpy="0 0 0" xyz="0 0 0"/>
      <geometry>
        <mesh filename="package://tori_description/meshes/servo.stl" scale=".001 .001 .001"/>
        --&gt;
        
      </geometry>
    </collision>
    <visual>
      <origin rpy="0 0 0" xyz="0 0 0"/>
      <geometry>
        <mesh filename="package://tori_description/meshes/servo.stl" scale=".001 .001 .001"/>
      </geometry>
      <material name="Black"/>
      <color rgba="0.0 0.0 0.0 0.0"/>
    </visual>
    <inertial>
      <origin rpy="0 0 0" xyz="0 0 0"/>
      <mass value="0.068"/>
      <inertia ixx="8.106666e-06" ixy="0.0" ixz="0.0" iyy="4.967866e-06" iyz="0.0" izz="4.967866e-06"/>
    </inertial>
  </link>
  <!--<xacro:rs_cam_stuff parent="torso_upper"/>-->
  <!--from here <xacro:sensor_d415 parent="torso_upper" name="camera">
      <origin xyz="0 0 .2" rpy="0 0 ${PI/2}"/>

    </xacro:sensor_d415> to here-->
  <!--<xacro:r parent="torso_upper">
      <origin xyz="0 0 .2" rpy="0 0 ${PI/2}"/>
    </xacro:sensor_d415>-->
  <!--name=camera  use_nominal_extrinsics:=false/>-->
  <!-- KINECT -->
  <!--
    <joint name="kinect_joint" type="fixed">
      <parent link="torso_upper"/>
      <child link="kinect_link"/>
      <origin xyz="0 0 .2" />
    </joint>
    <link name="kinect_link">
      <visual>
        <geometry>
          <box size="0.064 0.121 0.0381" />
        </geometry>
        <material name="Blue" />
      </visual>
      <inertial>
          <mass value="0.1" />
          <origin xyz="0 0 0" />
          <inertia ixx="0.01" ixy="0.0" ixz="0.0"
                   iyy="0.01" iyz="0.0"
                   izz="0.01" />
      </inertial>
    </link>

    <joint name="kinect_depth_joint" type="fixed">
      <origin xyz="0 0.028 0" rpy="0 0 0" />
      <parent link="kinect_link" />
      <child link="kinect_depth_frame" />
    </joint>

    <link name="kinect_depth_frame">
      <inertial>
          <mass value="0.0001" />
          <origin xyz="0 0 0" />
          <inertia ixx="0.0001" ixy="0.0" ixz="0.0"
                   iyy="0.0001" iyz="0.0"
                   izz="0.0001" />
      </inertial>
    </link>

    <joint name="depth_optical_joint" type="fixed">
      <origin xyz="0 0 0" rpy="${-PI/2} 0 ${-PI/2}" />
      <parent link="kinect_depth_frame" />
      <child link="kinect_depth_optical_frame" />
    </joint>

    <link name="kinect_depth_optical_frame">
      <inertial>
          <mass value="0.0001" />
          <origin xyz="0 0 0" />
          <inertia ixx="0.0001" ixy="0.0" ixz="0.0"
                   iyy="0.0001" iyz="0.0"
                   izz="0.0001" />
      </inertial>
    </link>  -->
  <!-- TORSO -->
  <joint name="dummy_joint" type="fixed">
    <parent link="dummy"/>
    <child link="pelvis"/>
    <origin rpy="0 0 0" xyz="0 0 0.7300000000000001"/>
    <!--<origin xyz="0 0 0" rpy="0 0 0"/>-->
  </joint>
  <joint name="spine_x" type="revolute">
    <parent link="pelvis"/>
    <child link="torso_lower"/>
    <origin rpy="0 0 0" xyz="0 0 .07"/>
    <axis xyz="1 0 0"/>
    <dynamics damping="0" friction="0"/>
    <limit effort="3.92" lower="-0.22" upper="0.22" velocity="1.97"/>
  </joint>
  <link name="torso_lower">
    <visual>
      <origin rpy="0 0 0" xyz="0 0 0"/>
      <geometry>
        <mesh filename="package://tori_description/meshes/spine_0.stl" scale=".001 .001 .001"/>
      </geometry>
      <material name="Black"/>
      <color rgba="0.0 0.0 0.0 0.0"/>
    </visual>
    <collision>
      <origin rpy="0 0 0" xyz="0 0 0"/>
      <geometry>
        <mesh filename="package://tori_description/meshes/spine_0.stl" scale=".001 .001 .001"/>
        --&gt;
        
      </geometry>
    </collision>
    <inertial>
      <origin rpy="0 0 0" xyz="-.003544949 -.000000002 .071470787"/>
      <mass value="0.084"/>
      <inertia ixx="0.000124387136" ixy="1.646853e-12" ixz="1.1473532e-05" iyy="0.000166922096" iyz="-1.89582e-11" izz="8.310168e-05"/>
    </inertial>
  </link>
  <joint name="spine_y_servo_0_joint" type="fixed">
    <parent link="torso_lower"/>
    <child link="spine_y_servo_0"/>
    <origin rpy="0 0 0" xyz="0 -.023 .110"/>
  </joint>
  <link name="spine_y_servo_0">
    <visual>
      <origin rpy="0 0 0" xyz="0 0 0"/>
      <geometry>
        <mesh filename="package://tori_description/meshes/servo.stl" scale=".001 .001 .001"/>
      </geometry>
      <material name="Black"/>
      <color rgba="0.0 0.0 0.0 0.0"/>
    </visual>
    <collision>
      <origin rpy="0 0 0" xyz="0 0 0"/>
      <geometry>
        <mesh filename="package://tori_description/meshes/servo.stl" scale=".001 .001 .001"/>
        --&gt;
        
      </geometry>
    </collision>
    <inertial>
      <origin rpy="0 0 0" xyz="0 0 0"/>
      <mass value="0.07"/>
      <inertia ixx="8.106666e-06" ixy="0.0" ixz="0.0" iyy="4.967866e-06" iyz="0.0" izz="4.967866e-06"/>
    </inertial>
  </link>
  <joint name="spine_y_servo_1_joint" type="fixed">
    <parent link="torso_lower"/>
    <child link="spine_y_servo_1"/>
    <origin rpy="0 0 0" xyz="0 .023 .110"/>
  </joint>
  <link name="spine_y_servo_1">
    <collision>
      <origin rpy="0 0 0" xyz="0 0 0"/>
      <geometry>
        <mesh filename="package://tori_description/meshes/servo.stl" scale=".001 .001 .001"/>
        --&gt;
        
      </geometry>
    </collision>
    <visual>
      <origin rpy="0 0 0" xyz="0 0 0"/>
      <geometry>
        <mesh filename="package://tori_description/meshes/servo.stl" scale=".001 .001 .001"/>
      </geometry>
      <material name="Black"/>
      <color rgba="0.0 0.0 0.0 0.0"/>
    </visual>
    <inertial>
      <origin rpy="0 0 0" xyz="0 0 0"/>
      <mass value="0.07"/>
      <inertia ixx="8.106666e-06" ixy="0.0" ixz="0.0" iyy="4.967866e-06" iyz="0.0" izz="4.967866e-06"/>
    </inertial>
  </link>
  <joint name="spine_y" type="revolute">
    <parent link="torso_lower"/>
    <child link="torso_mid"/>
    <origin rpy="0 0 0" xyz="0 0 0.12"/>
    <axis xyz="0 1 0"/>
    <dynamics damping="0" friction="0"/>
    <limit effort="3.92" lower="-0.22" upper="0.22" velocity="1.75"/>
  </joint>
  <link name="torso_mid">
    <collision>
      <origin rpy="0 0 0" xyz="0 0 0"/>
      <geometry>
        <mesh filename="package://tori_description/meshes/spine_1.stl" scale=".001 .001 .001"/>
        --&gt;
        
      </geometry>
    </collision>
    <visual>
      <origin rpy="0 0 0" xyz="0 0 0"/>
      <geometry>
        <mesh filename="package://tori_description/meshes/spine_1.stl" scale=".001 .001 .001"/>
      </geometry>
      <material name="Black"/>
      <color rgba="0.0 0.0 0.0 0.0"/>
    </visual>
    <inertial>
      <origin rpy="0 0 0" xyz="-.006629199 .013335866 .076523689"/>
      <mass value="0.075"/>
      <inertia ixx="0.00022848204799999998" ixy="7.6979135e-06" ixz="1.2358411e-05" iyy="0.0001590548" iyz="-2.623546e-05" izz="8.7150248e-05"/>
    </inertial>
  </link>
  <joint name="spine_z_servo_0_joint" type="fixed">
    <parent link="torso_mid"/>
    <child link="spine_z_servo_0"/>
    <origin rpy="0 0 0" xyz="0 .011 .094"/>
  </joint>
  <link name="spine_z_servo_0">
    <visual>
      <origin rpy="0 0 0" xyz="0 0 0"/>
      <geometry>
        <mesh filename="package://tori_description/meshes/servo.stl" scale=".001 .001 .001"/>
      </geometry>
      <material name="Black"/>
      <color rgba="0.0 0.0 0.0 0.0"/>
    </visual>
    <collision>
      <origin rpy="0 0 0" xyz="0 0 0"/>
      <geometry>
        <mesh filename="package://tori_description/meshes/servo.stl" scale=".001 .001 .001"/>
        --&gt;
        
      </geometry>
    </collision>
    <inertial>
      <origin rpy="0 0 0" xyz="0 0 0"/>
      <mass value="0.068"/>
      <inertia ixx="8.106666e-06" ixy="0.0" ixz="0.0" iyy="4.967866e-06" iyz="0.0" izz="4.967866e-06"/>
    </inertial>
  </link>
  <joint name="spine_z_servo_1_joint" type="fixed">
    <parent link="torso_mid"/>
    <child link="spine_z_servo_1"/>
    <origin rpy="0 0 0" xyz="0 .011 .140"/>
  </joint>
  <link name="spine_z_servo_1">
    <visual>
      <origin rpy="0 0 0" xyz="0 0 0"/>
      <geometry>
        <mesh filename="package://tori_description/meshes/servo.stl" scale=".001 .001 .001"/>
      </geometry>
      <material name="Black"/>
      <color rgba="0.0 0.0 0.0 0.0"/>
    </visual>
    <collision>
      <origin rpy="0 0 0" xyz="0 0 0"/>
      <geometry>
        <mesh filename="package://tori_description/meshes/servo.stl" scale=".001 .001 .001"/>
        --&gt;
        
      </geometry>
    </collision>
    <inertial>
      <origin rpy="0 0 0" xyz="0 0 0"/>
      <mass value="0.068"/>
      <inertia ixx="8.106666e-06" ixy="0.0" ixz="0.0" iyy="4.967866e-06" iyz="0.0" izz="4.967866e-06"/>
    </inertial>
  </link>
  <joint name="spine_z" type="revolute">
    <parent link="torso_mid"/>
    <child link="torso_upper"/>
    <origin rpy="0 0 0" xyz="0 0 0.116"/>
    <axis xyz="0 0 1"/>
    <dynamics damping="0" friction="0"/>
    <limit effort="3.92" lower="-0.22" upper="0.22" velocity="1.97"/>
  </joint>
  <link name="torso_upper">
    <visual>
      <origin rpy="0 0 0" xyz="0 0 0"/>
      <geometry>
        <mesh filename="package://tori_description/meshes/spine_2.stl" scale=".001 .001 .001"/>
      </geometry>
      <material name="Black"/>
      <color rgba="0.0 0.0 0.0 0.0"/>
    </visual>
    <collision>
      <origin rpy="0 0 0" xyz="0 0 0"/>
      <geometry>
        <mesh filename="package://tori_description/meshes/spine_2.stl" scale=".001 .001 .001"/>
        --&gt;
        
      </geometry>
    </collision>
    <inertial>
      <origin rpy="0 0 0" xyz=".001071245 -.026289972 .053334553"/>
      <mass value="0.125"/>
      <inertia ixx="0.000225709312" ixy="-1.6628644e-05" ixz="-1.4617055e-06" iyy="0.000609968576" iyz="-2.6089856e-05" izz="0.00051601312"/>
    </inertial>
  </link>
  <joint name="rpi_joint" type="fixed">
    <parent link="torso_upper"/>
    <child link="rpi"/>
    <origin rpy="1.5707963267948966 0 1.5707963267948966" xyz=".035 -.012 .077"/>
  </joint>
  <link name="rpi">
    <visual>
      <origin rpy="0 0 0" xyz="0 0 0"/>
      <geometry>
        <mesh filename="package://tori_description/meshes/rpi.stl" scale=".001 .001 .001"/>
      </geometry>
      <material name="Black"/>
      <color rgba="0.0 0.0 0.0 0.0"/>
    </visual>
    <collision>
      <origin rpy="0 0 0" xyz="0 0 0"/>
      <geometry>
        <mesh filename="package://tori_description/meshes/rpi.stl" scale=".001 .001 .001"/>
        --&gt;
        
      </geometry>
    </collision>
    <inertial>
      <origin rpy="0 0 0" xyz="0 0 0"/>
      <mass value="0.002"/>
      <inertia ixx="5.5916665e-06" ixy="0.0" ixz="0.0" iyy="1.7279166e-05" iyz="0.0" izz="1.1779167e-05"/>
    </inertial>
  </link>
  <joint name="pca_joint" type="fixed">
    <parent link="torso_upper"/>
    <child link="pca"/>
    <origin rpy="1.5707963267948966 0 1.5707963267948966" xyz="-.050 -.020 .076"/>
  </joint>
  <link name="pca">
    <visual>
      <origin rpy="0 0 0" xyz="0 0 0"/>
      <geometry>
        <mesh filename="package://tori_description/meshes/pca.stl" scale=".001 .001 .001"/>
      </geometry>
      <material name="Black"/>
      <color rgba="0.0 0.0 0.0 0.0"/>
    </visual>
    <collision>
      <origin rpy="0 0 0" xyz="0 0 0"/>
      <geometry>
        <mesh filename="package://tori_description/meshes/pca.stl" scale=".001 .001 .001"/>
        --&gt;
          
      </geometry>
    </collision>
    <inertial>
      <origin rpy="0 0 0" xyz="0 0 0"/>
      <mass value="0.011"/>
      <inertia ixx="1.5725e-07" ixy="0.0" ixz="0.0" iyy="1.05625e-06" iyz="0.0" izz="9.01e-07"/>
    </inertial>
  </link>
  <!-- LEFT ARM -->
  <!--
        <joint name="${prefix}shoulder_l_x" type="revolute">
          <parent link="${prefix}torso_upper" />
          <child link = "${prefix}shoulder_l0" />
          <origin xyz="${-width_torso_upper/2} 0 ${height_torso_upper - height_arm/2}" rpy="0 0 0"/>
          <axis xyz="1 0 0"/>
          <dynamics damping="${damping}" friction="${friction}"/>
          <limit lower="${lower_limit_shoulder_x}" upper="${upper_limit_shoulder_x}" effort="${effort_shoulder_x}" velocity="3"/>
        </joint>
        <link name="${prefix}shoulder_l0">
          <collision>
            <origin xyz="${-height_placeholder/2 - width_gap_shoulder_0} 0 0" rpy="0 ${-PI/2} 0"/>
            <geometry>
              <cylinder length="${height_placeholder}" radius="${radius_placeholder}"/>
            </geometry>
          </collision>
          <visual>
            <origin xyz="${-height_placeholder/2 - width_gap_shoulder_0} 0 0" rpy="0 ${-PI/2} 0"/>
            <geometry>
              <cylinder length="${height_placeholder}" radius="${radius_placeholder}"/>
            </geometry>
            <material name="Black"/>
              <color rgba="${Black}"/>
          </visual>
        <xacro:box_inertial height="${height_placeholder}" width="${radius_placeholder*2}" depth="${radius_placeholder*2}" mass="${mass_placeholder}" pos="${-height_placeholder/2 - width_gap_shoulder_0} 0 0" ang="0 ${-PI/2} 0">
        </xacro:box_inertial>
        </link>

        <joint name="${prefix}shoulder_l_y" type="revolute">
          <parent link="${prefix}shoulder_l0" />
          <child link = "${prefix}shoulder_l1" />
          <origin xyz="${-height_placeholder - width_gap_shoulder_0} 0 0" rpy="0 0 0"/>
          <axis xyz="0 1 0"/>
          <dynamics damping="${damping}" friction="${friction}"/>
          <limit lower="${lower_limit_shoulder_y}" upper="${upper_limit_shoulder_y}" effort="${effort_shoulder_y}" velocity="3"/>
        </joint>
        <link name="${prefix}shoulder_l1">
          <collision>
            <origin xyz="${-height_placeholder/2 - width_gap_shoulder_1} 0 0" rpy="0 ${-PI/2} 0"/>
            <geometry>
              <cylinder length="${height_placeholder}" radius="${radius_placeholder}"/>
            </geometry>
          </collision>
          <visual>
            <origin xyz="${-height_placeholder/2 - width_gap_shoulder_1} 0 0" rpy="0 ${-PI/2} 0"/>
            <geometry>
              <cylinder length="${height_placeholder}" radius="${radius_placeholder}"/>
            </geometry>
            <material name="Black"/>
              <color rgba="${Black}"/>
          </visual>
        <xacro:box_inertial height="${height_placeholder}" width="${radius_placeholder*2}" depth="${radius_placeholder*2}" mass="${mass_placeholder}" pos="${-height_placeholder/2 - width_gap_shoulder_1} 0 0" ang="0 ${-PI/2} 0">
        </xacro:box_inertial>
        </link>

        <joint name="${prefix}shoulder_l_z" type="revolute">
          <parent link="${prefix}shoulder_l1" />
          <child link = "${prefix}arm_l" />
          <origin xyz="${-height_placeholder - width_gap_shoulder_1} 0 0" rpy="0 0 0"/>
          <axis xyz="0 0 1"/>
          <dynamics damping="${damping}" friction="${friction}"/>
          <limit lower="${lower_limit_shoulder_z}" upper="${upper_limit_shoulder_z}" effort="${effort_shoulder_z}" velocity="3"/>
        </joint>

        <link name="arm_l">
          <collision>
            <origin xyz="${-width_arm/2 - width_gap_shoulder_2} 0 0" rpy="0 ${-PI/2} 0"/>
            <geometry>
              <cylinder length="${width_arm}" radius="${depth_arm/2}"/>
            </geometry>
          </collision>
          <visual>
            <origin xyz="${-width_arm/2 - width_gap_shoulder_2} 0 0" rpy="0 ${-PI/2} 0"/>
            <geometry>
              <cylinder length="${width_arm}" radius="${depth_arm/2}"/>
            </geometry>
            <material name="Black"/>
              <color rgba="${Black}"/>
          </visual>
        <xacro:box_inertial height="${width_arm}" width="${depth_arm}" depth="${depth_arm}" mass="${mass_arm}" pos="${-width_arm/2 - width_gap_shoulder_2} 0 0" ang="0 ${-PI/2} 0">
        </xacro:box_inertial>
        </link>

        <joint name="${prefix}elbow_l_z" type="revolute">
          <parent link="${prefix}arm_l" />
          <child link = "${prefix}forearm_l" />
          <origin xyz="${-width_arm - width_gap_elbow_0} 0 0" rpy="0 0 0"/>
          <axis xyz="0 0 1"/>
          <dynamics damping="${damping}" friction="${friction}"/>
          <limit lower="${lower_limit_elbow_z}" upper="${upper_limit_elbow_z}" effort="${effort_constant}" velocity="3"/>
        </joint>

        <link name="${prefix}forearm_l">
          <collision>
            <origin xyz="${-height_placeholder/2 - width_gap_elbow_0} 0 0" rpy="0 ${-PI/2} 0"/>
            <geometry>
              <cylinder length="${height_placeholder}" radius="${radius_placeholder}"/>
            </geometry>
          </collision>
          <visual>
            <origin xyz="${-height_placeholder/2 - width_gap_elbow_0} 0 0" rpy="0 ${-PI/2} 0"/>
            <geometry>
              <cylinder length="${height_placeholder}" radius="${radius_placeholder}"/>
            </geometry>
            <material name="Black"/>
              <color rgba="${Black}"/>
          </visual>
        <xacro:box_inertial height="${height_placeholder}" width="${radius_placeholder*2}" depth="${radius_placeholder*2}" mass="${mass_placeholder}" pos="${-height_placeholder/2 - width_gap_elbow_0} 0 0" ang="0 ${-PI/2} 0">
        </xacro:box_inertial>


        </link>

        <joint name="${prefix}elbow_l_x" type="revolute">
          <parent link="${prefix}forearm_l" />
          <child link = "${prefix}wrist_l0" />
          <origin xyz="${-height_placeholder - width_gap_elbow_0} 0 0" rpy="0 0 0"/>
          <axis xyz="1 0 0"/>
          <dynamics damping="${damping}" friction="${friction}"/>
          <limit lower="${lower_limit_elbow_x}" upper="${upper_limit_elbow_x}" effort="${effort_constant}" velocity="3"/>
        </joint>

        <link name="${prefix}wrist_l0">
          <collision>
            <origin xyz="${-width_forearm/2 - width_gap_elbow_1} 0 0" rpy="0 ${-PI/2} 0"/>
            <geometry>
              <cylinder length="${width_forearm}" radius="${depth_forearm/2}"/>
            </geometry>
          </collision>
          <visual>
            <origin xyz="${-width_forearm/2 - width_gap_elbow_1} 0 0" rpy="0 ${-PI/2} 0"/>
            <geometry>
              <cylinder length="${width_forearm}" radius="${depth_forearm/2}"/>
            </geometry>
            <material name="Black"/>
              <color rgba="${Black}"/>
          </visual>

        <xacro:box_inertial height="${width_forearm}" width="${depth_forearm}" depth="${depth_forearm}" mass="${mass_forearm}" pos="${-width_forearm/2 - width_gap_elbow_1} 0 0" ang="0 ${-PI/2} 0">
        </xacro:box_inertial>

        </link>

        <joint name="${prefix}wrist_l_z" type="revolute">
          <parent link="${prefix}wrist_l0" />
          <child link = "${prefix}wrist_l1" />
          <origin xyz="${-width_forearm - width_gap_wrist_0} 0 0" rpy="0 0 0"/>
          <axis xyz="0 0 1"/>
          <dynamics damping="${damping}" friction="${friction}"/>
          <limit lower="${lower_limit_wrist_z}" upper="${upper_limit_wrist_z}" effort="${effort_wrist_z}" velocity="3"/>
        </joint>

        <link name="${prefix}wrist_l1">
          <collision>
            <origin xyz="${-height_placeholder/2 - width_gap_wrist_0} 0 0" rpy="0 ${-PI/2} 0"/>
            <geometry>
              <cylinder length="${height_placeholder}" radius="${radius_placeholder}"/>
            </geometry>
          </collision>
          <visual>
            <origin xyz="${-height_placeholder/2 - width_gap_wrist_0} 0 0" rpy="0 ${-PI/2} 0"/>
            <geometry>
              <cylinder length="${height_placeholder}" radius="${radius_placeholder}"/>
            </geometry>
            <material name="Black"/>
              <color rgba="${Black}"/>
          </visual>
        <xacro:box_inertial height="${height_placeholder}" width="${radius_placeholder*2}" depth="${radius_placeholder*2}" mass="${mass_placeholder}" pos="${-height_placeholder/2 - width_gap_elbow_0} 0 0" ang="0 ${-PI/2} 0">
        </xacro:box_inertial>
        </link>

        <joint name="${prefix}wrist_l_y" type="revolute">
          <parent link="${prefix}wrist_l1" />
          <child link = "${prefix}hand_l" />
          <origin xyz="${-height_placeholder - width_gap_wrist_0} 0 0" rpy="0 0 0"/>
          <axis xyz="0 1 0"/>
          <dynamics damping="${damping}" friction="${friction}"/>
          <limit lower="${lower_limit_wrist_y}" upper="${upper_limit_wrist_y}" effort="${effort_wrist_y}" velocity="3"/>
        </joint>

        <link name="${prefix}hand_l">
        <collision>
          <origin xyz="${-width_palm/2 - width_gap_wrist_0} 0 0" rpy="0 0 0"/>
          <geometry>
    \t<box size="${width_palm} ${depth_palm} ${height_palm}"/>
          </geometry>
        </collision>
        <visual>
          <origin xyz="${-width_palm/2 - width_gap_wrist_0} 0 0" rpy="0 0 0"/>
          <geometry>
    \t<box size="${width_palm} ${depth_palm} ${height_palm}"/>
          </geometry>
          <material name="Black"/>
              <color rgba="${Black}"/>
        </visual>
          <xacro:box_inertial height="${height_palm}" width="${width_palm}" depth="${depth_palm}" mass="${mass_hand}" pos="${-width_palm/2 - width_gap_wrist_0} 0 0" ang="0 0 0">
          </xacro:box_inertial>
        </link>-->
  <!-- RIGHT ARM -->
  <!--
        <joint name="${prefix}shoulder_r_x" type="revolute">
          <parent link="${prefix}torso_upper" />
          <child link = "${prefix}shoulder_r0" />
          <origin xyz="${width_torso_upper/2} 0 ${height_torso_upper - height_arm/2}" rpy="0 0 0"/>
          <axis xyz="1 0 0"/>
          <dynamics damping="${damping}" friction="${friction}"/>
          <limit lower="${lower_limit_shoulder_x}" upper="${upper_limit_shoulder_x}" effort="${effort_shoulder_x}" velocity="3"/>
        </joint>
        <link name="${prefix}shoulder_r0">
          <collision>
            <origin xyz="${height_placeholder/2 + width_gap_shoulder_0} 0 0" rpy="0 ${PI/2} 0"/>
            <geometry>
              <cylinder length="${height_placeholder}" radius="${radius_placeholder}"/>
            </geometry>
          </collision>
          <visual>
            <origin xyz="${height_placeholder/2 + width_gap_shoulder_0} 0 0" rpy="0 ${PI/2} 0"/>
            <geometry>
              <cylinder length="${height_placeholder}" radius="${radius_placeholder}"/>
            </geometry>
            <material name="Black"/>
              <color rgba="${Black}"/>
          </visual>
        <xacro:box_inertial height="${height_placeholder}" width="${radius_placeholder*2}" depth="${radius_placeholder*2}" mass="${mass_placeholder}" pos="${height_placeholder/2 + width_gap_shoulder_0} 0 0" ang="0 ${PI/2} 0">
        </xacro:box_inertial>
        </link>

        <joint name="${prefix}shoulder_r_y" type="revolute">
          <parent link="${prefix}shoulder_r0" />
          <child link = "${prefix}shoulder_r1" />
          <origin xyz="${height_placeholder + width_gap_shoulder_0} 0 0" rpy="0 0 0"/>
          <axis xyz="0 1 0"/>
          <dynamics damping="${damping}" friction="${friction}"/>
          <limit lower="${lower_limit_shoulder_y}" upper="${upper_limit_shoulder_y}" effort="${effort_shoulder_y}" velocity="3"/>
        </joint>
        <link name="${prefix}shoulder_r1">
          <collision>
            <origin xyz="${height_placeholder/2 + width_gap_shoulder_1} 0 0" rpy="0 ${PI/2} 0"/>
            <geometry>
              <cylinder length="${height_placeholder}" radius="${radius_placeholder}"/>
            </geometry>
          </collision>
          <visual>
            <origin xyz="${height_placeholder/2 + width_gap_shoulder_1} 0 0" rpy="0 ${PI/2} 0"/>
            <geometry>
              <cylinder length="${height_placeholder}" radius="${radius_placeholder}"/>
            </geometry>
            <material name="Black"/>
              <color rgba="${Black}"/>
          </visual>
        <xacro:box_inertial height="${height_placeholder}" width="${radius_placeholder*2}" depth="${radius_placeholder*2}" mass="${mass_placeholder}" pos="${height_placeholder/2 + width_gap_shoulder_1} 0 0" ang="0 ${PI/2} 0">
        </xacro:box_inertial>
        </link>

        <joint name="${prefix}shoulder_r_z" type="revolute">
          <parent link="${prefix}shoulder_r1" />
          <child link = "${prefix}arm_r" />
          <origin xyz="${height_placeholder + width_gap_shoulder_1} 0 0" rpy="0 0 0"/>
          <axis xyz="0 0 -1"/>
          <dynamics damping="${damping}" friction="${friction}"/>
          <limit lower="${lower_limit_shoulder_z}" upper="${upper_limit_shoulder_z}" effort="${effort_shoulder_z}" velocity="3"/>
        </joint>

        <link name="${prefix}arm_r">
          <collision>
            <origin xyz="${width_arm/2 + width_gap_shoulder_2} 0 0" rpy="0 ${PI/2} 0"/>
            <geometry>
              <cylinder length="${width_arm}" radius="${depth_arm/2}"/>
            </geometry>
          </collision>
          <visual>
            <origin xyz="${width_arm/2 + width_gap_shoulder_2} 0 0" rpy="0 ${PI/2} 0"/>
            <geometry>
              <cylinder length="${width_arm}" radius="${depth_arm/2}"/>
            </geometry>
            <material name="Black"/>
              <color rgba="${Black}"/>
          </visual>
        <xacro:box_inertial height="${width_arm}" width="${depth_arm}" depth="${depth_arm}" mass="${mass_arm}" pos="${width_arm/2 + width_gap_shoulder_2} 0 0" ang="0 ${PI/2} 0">
        </xacro:box_inertial>
        </link>

        <joint name="${prefix}elbow_r_z" type="revolute">
          <parent link="${prefix}arm_r" />
          <child link = "${prefix}forearm_r" />
          <origin xyz="${width_arm + width_gap_elbow_0} 0 0" rpy="0 0 0"/>
          <axis xyz="0 0 -1"/>
          <dynamics damping="${damping}" friction="${friction}"/>
          <limit lower="${lower_limit_elbow_z}" upper="${upper_limit_elbow_z}" effort="${effort_constant}" velocity="3"/>
        </joint>

        <link name="${prefix}forearm_r">
          <collision>
            <origin xyz="${height_placeholder/2 + width_gap_elbow_0} 0 0" rpy="0 ${PI/2} 0"/>
            <geometry>
              <cylinder length="${height_placeholder}" radius="${radius_placeholder}"/>
            </geometry>
          </collision>
          <visual>
            <origin xyz="${height_placeholder/2 + width_gap_elbow_0} 0 0" rpy="0 ${PI/2} 0"/>
            <geometry>
              <cylinder length="${height_placeholder}" radius="${radius_placeholder}"/>
            </geometry>
            <material name="Black"/>
              <color rgba="${Black}"/>
          </visual>
        <xacro:box_inertial height="${height_placeholder}" width="${radius_placeholder*2}" depth="${radius_placeholder*2}" mass="${mass_placeholder}" pos="${height_placeholder/2 + width_gap_elbow_0} 0 0" ang="0 ${PI/2} 0">
        </xacro:box_inertial>
        </link>

        <joint name="${prefix}elbow_r_x" type="revolute">
          <parent link="${prefix}forearm_r" />
          <child link = "${prefix}wrist_r0" />
          <origin xyz="${height_placeholder + width_gap_elbow_0} 0 0" rpy="0 0 0"/>
          <axis xyz="1 0 0"/>
          <dynamics damping="${damping}" friction="${friction}"/>
          <limit lower="${lower_limit_elbow_x}" upper="${upper_limit_elbow_x}" effort="${effort_constant}" velocity="3"/>
        </joint>

        <link name="${prefix}wrist_r0">
          <collision>
            <origin xyz="${width_forearm/2 + width_gap_elbow_1} 0 0" rpy="0 ${PI/2} 0"/>
            <geometry>
              <cylinder length="${width_forearm}" radius="${depth_forearm/2}"/>
            </geometry>
          </collision>
          <visual>
            <origin xyz="${width_forearm/2 + width_gap_elbow_1} 0 0" rpy="0 ${PI/2} 0"/>
            <geometry>
              <cylinder length="${width_forearm}" radius="${depth_forearm/2}"/>
            </geometry>
            <material name="Black"/>
              <color rgba="${Black}"/>
          </visual>
        <xacro:box_inertial height="${width_forearm}" width="${depth_forearm}" depth="${depth_forearm}" mass="${mass_forearm}" pos="${width_forearm/2 + width_gap_elbow_1} 0 0" ang="0 ${PI/2} 0">
        </xacro:box_inertial>
        </link>

        <joint name="${prefix}wrist_r_z" type="revolute">
          <parent link="${prefix}wrist_r0" />
          <child link = "${prefix}wrist_r1" />
          <origin xyz="${width_forearm + width_gap_wrist_0} 0 0" rpy="0 0 0"/>
          <axis xyz="0 0 -1"/>
          <dynamics damping="${damping}" friction="${friction}"/>
          <limit lower="${lower_limit_wrist_z}" upper="${upper_limit_wrist_z}" effort="${effort_wrist_z}" velocity="3"/>
        </joint>

        <link name="${prefix}wrist_r1">
          <collision>
            <origin xyz="${height_placeholder/2 + width_gap_wrist_0} 0 0" rpy="0 ${PI/2} 0"/>
            <geometry>
              <cylinder length="${height_placeholder}" radius="${radius_placeholder}"/>
            </geometry>
          </collision>
          <visual>
            <origin xyz="${height_placeholder/2 + width_gap_wrist_0} 0 0" rpy="0 ${PI/2} 0"/>
            <geometry>
              <cylinder length="${height_placeholder}" radius="${radius_placeholder}"/>
            </geometry>
            <material name="Black"/>
              <color rgba="${Black}"/>
          </visual>
        <xacro:box_inertial height="${height_placeholder}" width="${radius_placeholder*2}" depth="${radius_placeholder*2}" mass="${mass_placeholder}" pos="${height_placeholder/2 + width_gap_elbow_0} 0 0" ang="0 ${PI/2} 0">
        </xacro:box_inertial>
        </link>

        <joint name="${prefix}wrist_r_y" type="revolute">
          <parent link="${prefix}wrist_r1" />
          <child link = "${prefix}hand_r" />
          <origin xyz="${height_placeholder + width_gap_wrist_0} 0 0" rpy="0 0 0"/>
          <axis xyz="0 1 0"/>
          <dynamics damping="${damping}" friction="${friction}"/>
          <limit lower="${lower_limit_wrist_y}" upper="${upper_limit_wrist_y}" effort="${effort_wrist_y}" velocity="3"/>
        </joint>
        <link name="${prefix}hand_r">
        <collision>
          <origin xyz="${width_palm/2 + width_gap_wrist_0} 0 0" rpy="0 0 0"/>
          <geometry>
    \t<box size="${width_palm} ${depth_palm} ${height_palm}"/>
          </geometry>
        </collision>
        <visual>
          <origin xyz="${width_palm/2 + width_gap_wrist_0} 0 0" rpy="0 0 0"/>
          <geometry>
    \t<box size="${width_palm} ${depth_palm} ${height_palm}"/>
          </geometry>
          <material name="Black"/>
              <color rgba="${Black}"/>
        </visual>
          <xacro:box_inertial height="${height_palm}" width="${width_palm}" depth="${depth_palm}" mass="${mass_hand}" pos="${width_palm/2 + width_gap_wrist_0} 0 0" ang="0 0 0">
          </xacro:box_inertial>
        </link>-->
  <!-- index finger r-->
  <!--
        <joint name="${prefix}finger_00y_joint_r" type="revolute">
          <parent link="${prefix}hand_r" />
          <child link = "${prefix}finger_0_base_r" />
          <origin xyz="${width_palm + width_gap_wrist_0} 0 ${height_palm/4 + square_finger/2}" rpy="0 0 0"/>
          <axis xyz="0 1 0"/>
          <dynamics damping="${damping}" friction="${friction}"/>
          <limit lower="${lower_limit_finger_y}" upper="${upper_limit_finger_y}" effort="${effort_wrist_y}" velocity="3"/>
        </joint>
        <link name="${prefix}finger_0_base_r">
          <collision>
            <origin xyz="${length_finger_base/2 + gap_finger_base} 0 0" rpy="0 0 0"/>
            <geometry>
              <box size="${length_finger_base} ${square_finger_base} ${square_finger_base}"/>
            </geometry>
          </collision>
          <visual>
            <origin xyz="${length_finger_base/2 + gap_finger_base} 0 0" rpy="0 0 0"/>
            <geometry>
              <box size="${length_finger_base} ${square_finger_base} ${square_finger_base}"/>
            </geometry>
            <material name="Black"/>
                <color rgba="${Black}"/>
          </visual>
            <xacro:box_inertial height="${length_finger_base}" width="${square_finger_base}" depth="${square_finger_base}" mass="${mass_finger_base}" pos="${length_finger_base/2 + gap_finger_base} 0 0" ang="0 ${PI/2} 0">
            </xacro:box_inertial>
        </link>

        <joint name="${prefix}finger_00x_joint_r" type="revolute">
          <parent link="${prefix}finger_0_base_r" />
          <child link = "${prefix}finger_00_r" />
          <origin xyz="${gap_finger_base + length_finger_base} 0 0" rpy="0 0 0"/>
          <axis xyz="1 0 0"/>
          <dynamics damping="${damping}" friction="${friction}"/>
          <limit lower="${lower_limit_finger_0}" upper="${upper_limit_finger_0}" effort="${effort_wrist_y}" velocity="3"/>
        </joint>

        <link name="${prefix}finger_00_r">
          <collision>
            <origin xyz="${length_finger/2 + gap_finger} 0 0" rpy="0 0 0"/>
            <geometry>
              <box size="${length_finger} ${square_finger} ${square_finger}"/>
            </geometry>
          </collision>
          <visual>
            <origin xyz="${length_finger/2 + gap_finger} 0 0" rpy="0 0 0"/>
            <geometry>
              <box size="${length_finger} ${square_finger} ${square_finger}"/>
            </geometry>
            <material name="Black"/>
                <color rgba="${Black}"/>
          </visual>
            <xacro:box_inertial height="${length_finger}" width="${square_finger}" depth="${square_finger}" mass="${mass_finger_00}" pos="${length_finger/2 + gap_finger} 0 0" ang="0 ${PI/2} 0">
            </xacro:box_inertial>
        </link>

        <joint name="${prefix}finger_01_joint_r" type="revolute">
          <parent link="${prefix}finger_00_r" />
          <child link = "${prefix}finger_01_r" />
          <origin xyz="${gap_finger + length_finger} 0 0" rpy="0 0 0"/>
          <axis xyz="1 0 0"/>
          <dynamics damping="${damping}" friction="${friction}"/>
          <limit lower="${lower_limit_finger_1}" upper="${upper_limit_finger_1}" effort="${effort_wrist_y}" velocity="3"/>
        </joint>
        <link name="${prefix}finger_01_r">
          <collision>
            <origin xyz="${length_finger/2 + gap_finger} 0 0" rpy="0 0 0"/>
            <geometry>
              <box size="${length_finger} ${square_finger} ${square_finger}"/>
            </geometry>
          </collision>
          <visual>
            <origin xyz="${length_finger/2 + gap_finger} 0 0" rpy="0 0 0"/>
            <geometry>
              <box size="${length_finger} ${square_finger} ${square_finger}"/>
            </geometry>
            <material name="Black"/>
                <color rgba="${Black}"/>
          </visual>
            <xacro:box_inertial height="${length_finger}" width="${square_finger}" depth="${square_finger}" mass="${mass_finger_00}" pos="${length_finger/2 + gap_finger} 0 0" ang="0 ${PI/2} 0">
            </xacro:box_inertial>
        </link>

        <joint name="${prefix}finger_02_joint_r" type="revolute">
          <parent link="${prefix}finger_01_r" />
          <child link = "${prefix}finger_02_r" />
          <origin xyz="${gap_finger + length_finger} 0 0" rpy="0 0 0"/>
          <axis xyz="1 0 0"/>
          <dynamics damping="${damping}" friction="${friction}"/>
          <limit lower="${lower_limit_finger_2}" upper="${upper_limit_finger_2}" effort="${effort_wrist_y}" velocity="3"/>
        </joint>
        <link name="${prefix}finger_02_r">
          <collision>
            <origin xyz="${length_finger/2 + gap_finger} 0 0" rpy="0 0 0"/>
            <geometry>
              <box size="${length_finger} ${square_finger} ${square_finger}"/>
            </geometry>
          </collision>
          <visual>
            <origin xyz="${length_finger/2 + gap_finger} 0 0" rpy="0 0 0"/>
            <geometry>
              <box size="${length_finger} ${square_finger} ${square_finger}"/>
            </geometry>
            <material name="Black"/>
                <color rgba="${Black}"/>
          </visual>
            <xacro:box_inertial height="${length_finger}" width="${square_finger}" depth="${square_finger}" mass="${mass_finger_00}" pos="${length_finger/2 + gap_finger} 0 0" ang="0 ${PI/2} 0">
            </xacro:box_inertial>
        </link>-->
  <!-- middle finger r -->
  <!--
        <joint name="${prefix}finger_10y_joint_r" type="revolute">
          <parent link="${prefix}hand_r" />
          <child link = "${prefix}finger_1_base_r" />
          <origin xyz="${width_palm + width_gap_wrist_0} 0 ${0 * height_palm/4 + square_finger/2}" rpy="0 0 0"/>
          <axis xyz="0 1 0"/>
          <dynamics damping="${damping}" friction="${friction}"/>
          <limit lower="${lower_limit_finger_y}" upper="${upper_limit_finger_y}" effort="${effort_wrist_y}" velocity="3"/>
        </joint>
        <link name="${prefix}finger_1_base_r">
          <collision>
            <origin xyz="${length_finger_base/2 + gap_finger_base} 0 0" rpy="0 0 0"/>
            <geometry>
              <box size="${length_finger_base} ${square_finger_base} ${square_finger_base}"/>
            </geometry>
          </collision>
          <visual>
            <origin xyz="${length_finger_base/2 + gap_finger_base} 0 0" rpy="0 0 0"/>
            <geometry>
              <box size="${length_finger_base} ${square_finger_base} ${square_finger_base}"/>
            </geometry>
            <material name="Black"/>
                <color rgba="${Black}"/>
          </visual>
            <xacro:box_inertial height="${length_finger_base}" width="${square_finger_base}" depth="${square_finger_base}" mass="${mass_finger_base}" pos="${length_finger_base/2 + gap_finger_base} 0 0" ang="0 ${PI/2} 0">
            </xacro:box_inertial>
        </link>


        <joint name="${prefix}finger_10x_joint_r" type="revolute">
          <parent link="${prefix}finger_1_base_r" />
          <child link = "${prefix}finger_10_r" />
          <origin xyz="${gap_finger_base + length_finger_base} 0 0" rpy="0 0 0"/>
          <axis xyz="1 0 0"/>
          <dynamics damping="${damping}" friction="${friction}"/>
          <limit lower="${lower_limit_finger_0}" upper="${upper_limit_finger_0}" effort="${effort_wrist_y}" velocity="3"/>
        </joint>
        <link name="${prefix}finger_10_r">
          <collision>
            <origin xyz="${length_finger/2 + gap_finger} 0 0" rpy="0 0 0"/>
            <geometry>
              <box size="${length_finger} ${square_finger} ${square_finger}"/>
            </geometry>
          </collision>
          <visual>
            <origin xyz="${length_finger/2 + gap_finger} 0 0" rpy="0 0 0"/>
            <geometry>
              <box size="${length_finger} ${square_finger} ${square_finger}"/>
            </geometry>
            <material name="Black"/>
                <color rgba="${Black}"/>
          </visual>
            <xacro:box_inertial height="${length_finger}" width="${square_finger}" depth="${square_finger}" mass="${mass_finger_00}" pos="${length_finger/2 + gap_finger} 0 0" ang="0 ${PI/2} 0">
            </xacro:box_inertial>
        </link>

        <joint name="${prefix}finger_11_joint_r" type="revolute">
          <parent link="${prefix}finger_10_r" />
          <child link = "${prefix}finger_11_r" />
          <origin xyz="${gap_finger + length_finger} 0 0" rpy="0 0 0"/>
          <axis xyz="1 0 0"/>
          <dynamics damping="${damping}" friction="${friction}"/>
          <limit lower="${lower_limit_finger_1}" upper="${upper_limit_finger_1}" effort="${effort_wrist_y}" velocity="3"/>
        </joint>
        <link name="${prefix}finger_11_r">
          <collision>
            <origin xyz="${length_finger/2 + gap_finger} 0 0" rpy="0 0 0"/>
            <geometry>
              <box size="${length_finger} ${square_finger} ${square_finger}"/>
            </geometry>
          </collision>
          <visual>
            <origin xyz="${length_finger/2 + gap_finger} 0 0" rpy="0 0 0"/>
            <geometry>
              <box size="${length_finger} ${square_finger} ${square_finger}"/>
            </geometry>
            <material name="Black"/>
                <color rgba="${Black}"/>
          </visual>
            <xacro:box_inertial height="${length_finger}" width="${square_finger}" depth="${square_finger}" mass="${mass_finger_00}" pos="${length_finger/2 + gap_finger} 0 0" ang="0 ${PI/2} 0">
            </xacro:box_inertial>
        </link>

        <joint name="${prefix}finger_12_joint_r" type="revolute">
          <parent link="${prefix}finger_11_r" />
          <child link = "${prefix}finger_12_r" />
          <origin xyz="${gap_finger + length_finger} 0 0" rpy="0 0 0"/>
          <axis xyz="1 0 0"/>
          <dynamics damping="${damping}" friction="${friction}"/>
          <limit lower="${lower_limit_finger_2}" upper="${upper_limit_finger_2}" effort="${effort_wrist_y}" velocity="3"/>
        </joint>
        <link name="${prefix}finger_12_r">
          <collision>
            <origin xyz="${length_finger/2 + gap_finger} 0 0" rpy="0 0 0"/>
            <geometry>
              <box size="${length_finger} ${square_finger} ${square_finger}"/>
            </geometry>
          </collision>
          <visual>
            <origin xyz="${length_finger/2 + gap_finger} 0 0" rpy="0 0 0"/>
            <geometry>
              <box size="${length_finger} ${square_finger} ${square_finger}"/>
            </geometry>
            <material name="Black"/>
                <color rgba="${Black}"/>
          </visual>
            <xacro:box_inertial height="${length_finger}" width="${square_finger}" depth="${square_finger}" mass="${mass_finger_00}" pos="${length_finger/2 + gap_finger} 0 0" ang="0 ${PI/2} 0">
            </xacro:box_inertial>
        </link>-->
  <!-- ring finger r -->
  <!--
        <joint name="${prefix}finger_20y_joint_r" type="revolute">
          <parent link="${prefix}hand_r" />
          <child link = "${prefix}finger_2_base_r" />
          <origin xyz="${width_palm + width_gap_wrist_0} 0 ${-1 * height_palm/4 + square_finger/2}" rpy="0 0 0"/>
          <axis xyz="0 1 0"/>
          <dynamics damping="${damping}" friction="${friction}"/>
          <limit lower="${lower_limit_finger_y}" upper="${upper_limit_finger_y}" effort="${effort_wrist_y}" velocity="3"/>
        </joint>
        <link name="${prefix}finger_2_base_r">
          <collision>
            <origin xyz="${length_finger_base/2 + gap_finger_base} 0 0" rpy="0 0 0"/>
            <geometry>
              <box size="${length_finger_base} ${square_finger_base} ${square_finger_base}"/>
            </geometry>
          </collision>
          <visual>
            <origin xyz="${length_finger_base/2 + gap_finger_base} 0 0" rpy="0 0 0"/>
            <geometry>
              <box size="${length_finger_base} ${square_finger_base} ${square_finger_base}"/>
            </geometry>
            <material name="Black"/>
                <color rgba="${Black}"/>
          </visual>
            <xacro:box_inertial height="${length_finger_base}" width="${square_finger_base}" depth="${square_finger_base}" mass="${mass_finger_base}" pos="${length_finger_base/2 + gap_finger_base} 0 0" ang="0 ${PI/2} 0">
            </xacro:box_inertial>
        </link>


        <joint name="${prefix}finger_20x_joint_r" type="revolute">
          <parent link="${prefix}finger_2_base_r" />
          <child link = "${prefix}finger_20_r" />
          <origin xyz="${gap_finger_base + length_finger_base} 0 0" rpy="0 0 0"/>
          <axis xyz="1 0 0"/>
          <dynamics damping="${damping}" friction="${friction}"/>
          <limit lower="${lower_limit_finger_0}" upper="${upper_limit_finger_0}" effort="${effort_wrist_y}" velocity="3"/>
        </joint>
        <link name="${prefix}finger_20_r">
          <collision>
            <origin xyz="${length_finger/2 + gap_finger} 0 0" rpy="0 0 0"/>
            <geometry>
              <box size="${length_finger} ${square_finger} ${square_finger}"/>
            </geometry>
          </collision>
          <visual>
            <origin xyz="${length_finger/2 + gap_finger} 0 0" rpy="0 0 0"/>
            <geometry>
              <box size="${length_finger} ${square_finger} ${square_finger}"/>
            </geometry>
            <material name="Black"/>
                <color rgba="${Black}"/>
          </visual>
            <xacro:box_inertial height="${length_finger}" width="${square_finger}" depth="${square_finger}" mass="${mass_finger_00}" pos="${length_finger/2 + gap_finger} 0 0" ang="0 ${PI/2} 0">
            </xacro:box_inertial>
        </link>

        <joint name="${prefix}finger_21_joint_r" type="revolute">
          <parent link="${prefix}finger_20_r" />
          <child link = "${prefix}finger_21_r" />
          <origin xyz="${gap_finger + length_finger} 0 0" rpy="0 0 0"/>
          <axis xyz="1 0 0"/>
          <dynamics damping="${damping}" friction="${friction}"/>
          <limit lower="${lower_limit_finger_1}" upper="${upper_limit_finger_1}" effort="${effort_wrist_y}" velocity="3"/>
        </joint>
        <link name="${prefix}finger_21_r">
          <collision>
            <origin xyz="${length_finger/2 + gap_finger} 0 0" rpy="0 0 0"/>
            <geometry>
              <box size="${length_finger} ${square_finger} ${square_finger}"/>
            </geometry>
          </collision>
          <visual>
            <origin xyz="${length_finger/2 + gap_finger} 0 0" rpy="0 0 0"/>
            <geometry>
              <box size="${length_finger} ${square_finger} ${square_finger}"/>
            </geometry>
            <material name="Black"/>
                <color rgba="${Black}"/>
          </visual>
            <xacro:box_inertial height="${length_finger}" width="${square_finger}" depth="${square_finger}" mass="${mass_finger_00}" pos="${length_finger/2 + gap_finger} 0 0" ang="0 ${PI/2} 0">
            </xacro:box_inertial>
        </link>

        <joint name="${prefix}finger_22_joint_r" type="revolute">
          <parent link="${prefix}finger_21_r" />
          <child link = "${prefix}finger_22_r" />
          <origin xyz="${gap_finger + length_finger} 0 0" rpy="0 0 0"/>
          <axis xyz="1 0 0"/>
          <dynamics damping="${damping}" friction="${friction}"/>
          <limit lower="${lower_limit_finger_2}" upper="${upper_limit_finger_2}" effort="${effort_wrist_y}" velocity="3"/>
        </joint>
        <link name="${prefix}finger_22_r">
          <collision>
            <origin xyz="${length_finger/2 + gap_finger} 0 0" rpy="0 0 0"/>
            <geometry>
              <box size="${length_finger} ${square_finger} ${square_finger}"/>
            </geometry>
          </collision>
          <visual>
            <origin xyz="${length_finger/2 + gap_finger} 0 0" rpy="0 0 0"/>
            <geometry>
              <box size="${length_finger} ${square_finger} ${square_finger}"/>
            </geometry>
            <material name="Black"/>
                <color rgba="${Black}"/>
          </visual>
            <xacro:box_inertial height="${length_finger}" width="${square_finger}" depth="${square_finger}" mass="${mass_finger_00}" pos="${length_finger/2 + gap_finger} 0 0" ang="0 ${PI/2} 0">
            </xacro:box_inertial>
        </link>-->
  <!-- pinky finger r -->
  <!--
        <joint name="${prefix}finger_30y_joint_r" type="revolute">
          <parent link="${prefix}hand_r" />
          <child link = "${prefix}finger_3_base_r" />
          <origin xyz="${width_palm + width_gap_wrist_0} 0 ${-2 * height_palm/4 + square_finger/2}" rpy="0 0 0"/>
          <axis xyz="0 1 0"/>
          <dynamics damping="${damping}" friction="${friction}"/>
          <limit lower="${lower_limit_finger_y}" upper="${upper_limit_finger_y}" effort="${effort_wrist_y}" velocity="3"/>
        </joint>
        <link name="${prefix}finger_3_base_r">
          <collision>
            <origin xyz="${length_finger_base/2 + gap_finger_base} 0 0" rpy="0 0 0"/>
            <geometry>
              <box size="${length_finger_base} ${square_finger_base} ${square_finger_base}"/>
            </geometry>
          </collision>
          <visual>
            <origin xyz="${length_finger_base/2 + gap_finger_base} 0 0" rpy="0 0 0"/>
            <geometry>
              <box size="${length_finger_base} ${square_finger_base} ${square_finger_base}"/>
            </geometry>
            <material name="Black"/>
                <color rgba="${Black}"/>
          </visual>
            <xacro:box_inertial height="${length_finger_base}" width="${square_finger_base}" depth="${square_finger_base}" mass="${mass_finger_base}" pos="${length_finger_base/2 + gap_finger_base} 0 0" ang="0 ${PI/2} 0">
            </xacro:box_inertial>
        </link>


        <joint name="${prefix}finger_30x_joint_r" type="revolute">
          <parent link="${prefix}finger_3_base_r" />
          <child link = "${prefix}finger_30_r" />
          <origin xyz="${gap_finger_base + length_finger_base} 0 0" rpy="0 0 0"/>
          <axis xyz="1 0 0"/>
          <dynamics damping="${damping}" friction="${friction}"/>
          <limit lower="${lower_limit_finger_0}" upper="${upper_limit_finger_0}" effort="${effort_wrist_y}" velocity="3"/>
        </joint>
        <link name="${prefix}finger_30_r">
          <collision>
            <origin xyz="${length_finger/2 + gap_finger} 0 0" rpy="0 0 0"/>
            <geometry>
              <box size="${length_finger} ${square_finger} ${square_finger}"/>
            </geometry>
          </collision>
          <visual>
            <origin xyz="${length_finger/2 + gap_finger} 0 0" rpy="0 0 0"/>
            <geometry>
              <box size="${length_finger} ${square_finger} ${square_finger}"/>
            </geometry>
            <material name="Black"/>
                <color rgba="${Black}"/>
          </visual>
            <xacro:box_inertial height="${length_finger}" width="${square_finger}" depth="${square_finger}" mass="${mass_finger_00}" pos="${length_finger/2 + gap_finger} 0 0" ang="0 ${PI/2} 0">
            </xacro:box_inertial>
        </link>

        <joint name="${prefix}finger_31_joint_r" type="revolute">
          <parent link="${prefix}finger_30_r" />
          <child link = "${prefix}finger_31_r" />
          <origin xyz="${gap_finger + length_finger} 0 0" rpy="0 0 0"/>
          <axis xyz="1 0 0"/>
          <dynamics damping="${damping}" friction="${friction}"/>
          <limit lower="${lower_limit_finger_1}" upper="${upper_limit_finger_1}" effort="${effort_wrist_y}" velocity="3"/>
        </joint>
        <link name="${prefix}finger_31_r">
          <collision>
            <origin xyz="${length_finger/2 + gap_finger} 0 0" rpy="0 0 0"/>
            <geometry>
              <box size="${length_finger} ${square_finger} ${square_finger}"/>
            </geometry>
          </collision>
          <visual>
            <origin xyz="${length_finger/2 + gap_finger} 0 0" rpy="0 0 0"/>
            <geometry>
              <box size="${length_finger} ${square_finger} ${square_finger}"/>
            </geometry>
            <material name="Black"/>
                <color rgba="${Black}"/>
          </visual>
            <xacro:box_inertial height="${length_finger}" width="${square_finger}" depth="${square_finger}" mass="${mass_finger_00}" pos="${length_finger/2 + gap_finger} 0 0" ang="0 ${PI/2} 0">
            </xacro:box_inertial>
        </link>

        <joint name="${prefix}finger_32_joint_r" type="revolute">
          <parent link="${prefix}finger_31_r" />
          <child link = "${prefix}finger_32_r" />
          <origin xyz="${gap_finger + length_finger} 0 0" rpy="0 0 0"/>
          <axis xyz="1 0 0"/>
          <dynamics damping="${damping}" friction="${friction}"/>
          <limit lower="${lower_limit_finger_2}" upper="${upper_limit_finger_2}" effort="${effort_wrist_y}" velocity="3"/>
        </joint>
        <link name="${prefix}finger_32_r">
          <collision>
            <origin xyz="${length_finger/2 + gap_finger} 0 0" rpy="0 0 0"/>
            <geometry>
              <box size="${length_finger} ${square_finger} ${square_finger}"/>
            </geometry>
          </collision>
          <visual>
            <origin xyz="${length_finger/2 + gap_finger} 0 0" rpy="0 0 0"/>
            <geometry>
              <box size="${length_finger} ${square_finger} ${square_finger}"/>
            </geometry>
            <material name="Black"/>
                <color rgba="${Black}"/>
          </visual>
            <xacro:box_inertial height="${length_finger}" width="${square_finger}" depth="${square_finger}" mass="${mass_finger_00}" pos="${length_finger/2 + gap_finger} 0 0" ang="0 ${PI/2} 0">
            </xacro:box_inertial>
        </link>-->
  <!-- thumb r -->
  <!--TODO: add thumb_y-->
  <!--
        <joint name="${prefix}thumb_y_joint_r" type="revolute">
          <parent link="${prefix}hand_r" />
          <child link = "${prefix}thumb_base_r" />
          <origin xyz="${width_palm/4 + width_gap_wrist_0} 0 ${height_palm/2}" rpy="0 0 0"/>
          <axis xyz="0 1 0"/>
          <dynamics damping="${damping}" friction="${friction}"/>
          <limit lower="${lower_limit_finger_y}" upper="${upper_limit_finger_y}" effort="${effort_wrist_y}" velocity="3"/>
        </joint>
        <link name="${prefix}thumb_base_r">
          <collision>
            <origin xyz="0 0 ${length_finger_base/2 + gap_finger_base}" rpy="0 0 0"/>
            <geometry>
              <box size="${length_finger_base} ${square_finger_base} ${square_finger_base}"/>
            </geometry>
          </collision>
          <visual>
            <origin xyz="0 0 ${length_finger_base/2 + gap_finger_base}" rpy="0 0 0"/>
            <geometry>
              <box size="${length_finger_base} ${square_finger_base} ${square_finger_base}"/>
            </geometry>
            <material name="Black"/>
                <color rgba="${Black}"/>
          </visual>
            <xacro:box_inertial height="${length_finger_base}" width="${square_finger_base}" depth="${square_finger_base}" mass="${mass_finger_base}" pos="${length_finger_base/2 + gap_finger_base} 0 0" ang="0 ${PI/2} 0">
            </xacro:box_inertial>
        </link>



        <joint name="${prefix}thumb_0_joint_r" type="revolute">
          <parent link="${prefix}thumb_base_r" />
          <child link = "${prefix}thumb_0_r" />
          <origin xyz="0 0 ${gap_finger + length_finger_base}" rpy="0 ${-PI/2} 0"/>
          <axis xyz="0 0 1"/>
          <dynamics damping="${damping}" friction="${friction}"/>
          <limit lower="${lower_limit_thumb_y}" upper="${upper_limit_thumb_y}" effort="${effort_wrist_y}" velocity="3"/>
        </joint>
        <link name="${prefix}thumb_0_r">
          <collision>
            <origin xyz="${length_finger/2 + gap_finger} 0 0" rpy="0 0 0"/>
            <geometry>
              <box size="${length_finger} ${square_finger} ${square_finger}"/>
            </geometry>
          </collision>
          <visual>
            <origin xyz="${length_finger/2 + gap_finger} 0 0" rpy="0 0 0"/>
            <geometry>
              <box size="${length_finger} ${square_finger} ${square_finger}"/>
            </geometry>
            <material name="Black"/>
                <color rgba="${Black}"/>
          </visual>
            <xacro:box_inertial height="${length_finger}" width="${square_finger}" depth="${square_finger}" mass="${mass_finger_00}" pos="${length_finger/2 + gap_finger} 0 0" ang="0 ${PI/2} 0">
            </xacro:box_inertial>
        </link>

        <joint name="${prefix}thumb_1_joint_r" type="revolute">
          <parent link="${prefix}thumb_0_r" />
          <child link = "${prefix}thumb_1_r" />
          <origin xyz="${gap_finger + length_finger} 0 0" rpy="0 0 0"/>
          <axis xyz="0 0 1"/>
          <dynamics damping="${damping}" friction="${friction}"/>
          <limit lower="${lower_limit_thumb_0}" upper="${upper_limit_wrist_y}" effort="${effort_wrist_y}" velocity="3"/>
        </joint>
        <link name="${prefix}thumb_1_r">
          <collision>
            <origin xyz="${length_finger/2 + gap_finger} 0 0" rpy="0 0 0"/>
            <geometry>
              <box size="${length_finger} ${square_finger} ${square_finger}"/>
            </geometry>
          </collision>
          <visual>
            <origin xyz="${length_finger/2 + gap_finger} 0 0" rpy="0 0 0"/>
            <geometry>
              <box size="${length_finger} ${square_finger} ${square_finger}"/>
            </geometry>
            <material name="Black"/>
                <color rgba="${Black}"/>
          </visual>
            <xacro:box_inertial height="${length_finger}" width="${square_finger}" depth="${square_finger}" mass="${mass_finger_00}" pos="${length_finger/2 + gap_finger} 0 0" ang="0 ${PI/2} 0">
            </xacro:box_inertial>
        </link>

        <joint name="${prefix}thumb_2_joint_r" type="revolute">
          <parent link="${prefix}thumb_1_r" />
          <child link = "${prefix}thumb_2_r" />
          <origin xyz="${gap_finger + length_finger} 0 0" rpy="0 0 0"/>
          <axis xyz="0 0 1"/>
          <dynamics damping="${damping}" friction="${friction}"/>
          <limit lower="${lower_limit_wrist_y}" upper="${upper_limit_wrist_y}" effort="${effort_wrist_y}" velocity="3"/>
        </joint>
        <link name="${prefix}thumb_2_r">
          <collision>
            <origin xyz="${length_finger/2 + gap_finger} 0 0" rpy="0 0 0"/>
            <geometry>
              <box size="${length_finger} ${square_finger} ${square_finger}"/>
            </geometry>
          </collision>
          <visual>
            <origin xyz="${length_finger/2 + gap_finger} 0 0" rpy="0 0 0"/>
            <geometry>
              <box size="${length_finger} ${square_finger} ${square_finger}"/>
            </geometry>
            <material name="Black"/>
                <color rgba="${Black}"/>
          </visual>
            <xacro:box_inertial height="${length_finger}" width="${square_finger}" depth="${square_finger}" mass="${mass_finger_00}" pos="${length_finger/2 + gap_finger} 0 0" ang="0 ${PI/2} 0">
            </xacro:box_inertial>
        </link>-->
  <!-- RIGHT LEG -->
  <joint name="hip_r_z" type="revolute">
    <parent link="pelvis"/>
    <child link="hip_r_z_x"/>
    <origin rpy="0 0 0" xyz="0.1 0 0"/>
    <axis xyz="0 0 1"/>
    <dynamics damping="0"/>
    <limit effort="3.92" lower="-0.78" upper="0.78" velocity="1.75"/>
  </joint>
  <link name="hip_r_z_x">
    <visual>
      <origin rpy="0 0 0" xyz="0 0 0"/>
      <geometry>
        <mesh filename="package://tori_description/meshes/hip_z_x_r.stl" scale=".001 .001 .001"/>
      </geometry>
      <material name="Black"/>
      <color rgba="0.0 0.0 0.0 0.0"/>
    </visual>
    <collision>
      <origin rpy="0 0 0" xyz="0 0 0"/>
      <geometry>
        <mesh filename="package://tori_description/meshes/hip_z_x_r.stl" scale=".001 .001 .001"/>
        --&gt;
          
      </geometry>
    </collision>
    <inertial>
      <origin rpy="0 0 0" xyz=".017571852 -.000349534 -.040100899"/>
      <mass value="0.121"/>
      <inertia ixx="0.000555098688" ixy="-2.3181858e-05" ixz="-0.00012467436799999999" iyy="0.000702137664" iyz="-7.1664776e-05" izz="0.00028148224"/>
    </inertial>
  </link>
  <joint name="hip_r_x_servo_0_joint" type="fixed">
    <parent link="hip_r_z_x"/>
    <child link="hip_r_x_servo_0"/>
    <origin rpy="0 0 1.5707963267948966" xyz="-.040 0 -.090"/>
  </joint>
  <link name="hip_r_x_servo_0">
    <visual>
      <origin rpy="0 0 0" xyz="0 0 0"/>
      <geometry>
        <mesh filename="package://tori_description/meshes/servo.stl" scale=".001 .001 .001"/>
      </geometry>
      <material name="Black"/>
      <color rgba="0.0 0.0 0.0 0.0"/>
    </visual>
    <collision>
      <origin rpy="0 0 0" xyz="0 0 0"/>
      <geometry>
        <mesh filename="package://tori_description/meshes/servo.stl" scale=".001 .001 .001"/>
        --&gt;
          
      </geometry>
    </collision>
    <inertial>
      <origin rpy="0 0 0" xyz="0 0 0"/>
      <mass value="0.07"/>
      <inertia ixx="8.106666e-06" ixy="0.0" ixz="0.0" iyy="4.967866e-06" iyz="0.0" izz="4.967866e-06"/>
    </inertial>
  </link>
  <joint name="hip_r_x_servo_1_joint" type="fixed">
    <parent link="hip_r_z_x"/>
    <child link="hip_r_x_servo_1"/>
    <origin rpy="0 0 1.5707963267948966" xyz=".050 0 -.090"/>
  </joint>
  <link name="hip_r_x_servo_1">
    <visual>
      <origin rpy="0 0 0" xyz="0 0 0"/>
      <geometry>
        <mesh filename="package://tori_description/meshes/servo.stl" scale=".001 .001 .001"/>
      </geometry>
      <material name="Black"/>
      <color rgba="0.0 0.0 0.0 0.0"/>
    </visual>
    <collision>
      <origin rpy="0 0 0" xyz="0 0 0"/>
      <geometry>
        <mesh filename="package://tori_description/meshes/servo.stl" scale=".001 .001 .001"/>
        --&gt;
          
      </geometry>
    </collision>
    <inertial>
      <origin rpy="0 0 0" xyz="0 0 0"/>
      <mass value="0.07"/>
      <inertia ixx="8.106666e-06" ixy="0.0" ixz="0.0" iyy="4.967866e-06" iyz="0.0" izz="4.967866e-06"/>
    </inertial>
  </link>
  <joint name="hip_r_x" type="revolute">
    <parent link="hip_r_z_x"/>
    <child link="hip_r_x_y"/>
    <origin rpy="0 0 0" xyz="0 0 -0.1"/>
    <axis xyz="1 0 0"/>
    <dynamics damping="0"/>
    <limit effort="3.92" lower="0" upper="0.8" velocity="1.75"/>
  </joint>
  <link name="hip_r_x_y">
    <visual>
      <origin rpy="0 0 0" xyz="0 0 0"/>
      <geometry>
        <mesh filename="package://tori_description/meshes/hip_x_y_r.stl" scale=".001 .001 .001"/>
      </geometry>
      <material name="Black"/>
      <color rgba="0.0 0.0 0.0 0.0"/>
    </visual>
    <collision>
      <origin rpy="0 0 0" xyz="0 0 0"/>
      <geometry>
        <mesh filename="package://tori_description/meshes/hip_x_y_r.stl" scale=".001 .001 .001"/>
        --&gt;
          
      </geometry>
    </collision>
    <inertial>
      <origin rpy="0 0 0" xyz=".001916841 .000003669 -.019280025"/>
      <mass value="0.057"/>
      <inertia ixx="9.0326312e-05" ixy="3.7192734e-11" ixz="2.91097875e-06" iyy="0.000127017272" iyz="6.164478516e-09" izz="0.000164451008"/>
    </inertial>
  </link>
  <joint name="hip_r_y" type="revolute">
    <parent link="hip_r_x_y"/>
    <child link="thigh_r"/>
    <origin rpy="0 0 0" xyz="0 0 -0.035"/>
    <axis xyz="0 1 0"/>
    <dynamics damping="0"/>
    <limit effort="3.92" lower="-0.52" upper="0.78" velocity="1.75"/>
  </joint>
  <link name="thigh_r">
    <visual>
      <origin rpy="0 0 0" xyz="0 0 0"/>
      <geometry>
        <mesh filename="package://tori_description/meshes/thigh_r.stl" scale=".001 .001 .001"/>
      </geometry>
      <material name="Black"/>
      <color rgba="0.0 0.0 0.0 0.0"/>
    </visual>
    <collision>
      <origin rpy="0 0 0" xyz="0 0 0"/>
      <geometry>
        <mesh filename="package://tori_description/meshes/thigh_r_collision.stl" scale=".001 .001 .001"/>
      </geometry>
    </collision>
    <inertial>
      <origin rpy="0 0 0" xyz="-.002060035 .006943111 -.137971710"/>
      <mass value="0.343"/>
      <inertia ixx="0.002767439104" ixy="-3.4047525e-07" ixz="8.016495e-06" iyy="0.0027336176639999998" iyz="0.000450212992" izz="0.00210200128"/>
    </inertial>
  </link>
  <joint name="hip_r_y_servo_0_joint" type="fixed">
    <parent link="thigh_r"/>
    <child link="hip_r_y_servo_0"/>
    <origin rpy="0 0 0" xyz="0 .035 -.011"/>
  </joint>
  <link name="hip_r_y_servo_0">
    <visual>
      <origin rpy="0 0 0" xyz="0 0 0"/>
      <geometry>
        <mesh filename="package://tori_description/meshes/servo.stl" scale=".001 .001 .001"/>
      </geometry>
      <material name="Black"/>
      <color rgba="0.0 0.0 0.0 0.0"/>
    </visual>
    <collision>
      <origin rpy="0 0 0" xyz="0 0 0"/>
      <geometry>
        <mesh filename="package://tori_description/meshes/servo.stl" scale=".001 .001 .001"/>
        --&gt;
          
      </geometry>
    </collision>
    <inertial>
      <origin rpy="0 0 0" xyz="0 0 0"/>
      <mass value="0.07"/>
      <inertia ixx="8.106666e-06" ixy="0.0" ixz="0.0" iyy="4.967866e-06" iyz="0.0" izz="4.967866e-06"/>
    </inertial>
  </link>
  <joint name="hip_r_y_servo_1_joint" type="fixed">
    <parent link="thigh_r"/>
    <child link="hip_r_y_servo_1"/>
    <origin rpy="0 0 0" xyz="0 -.035 -.011"/>
  </joint>
  <link name="hip_r_y_servo_1">
    <visual>
      <origin rpy="0 0 0" xyz="0 0 0"/>
      <geometry>
        <mesh filename="package://tori_description/meshes/servo.stl" scale=".001 .001 .001"/>
      </geometry>
      <material name="Black"/>
      <color rgba="0.0 0.0 0.0 0.0"/>
    </visual>
    <collision>
      <origin rpy="0 0 0" xyz="0 0 0"/>
      <geometry>
        <mesh filename="package://tori_description/meshes/servo.stl" scale=".001 .001 .001"/>
        --&gt;
          
      </geometry>
    </collision>
    <inertial>
      <origin rpy="0 0 0" xyz="0 0 0"/>
      <mass value="0.07"/>
      <inertia ixx="8.106666e-06" ixy="0.0" ixz="0.0" iyy="4.967866e-06" iyz="0.0" izz="4.967866e-06"/>
    </inertial>
  </link>
  <joint name="knee_r_servo_0_joint" type="fixed">
    <parent link="thigh_r"/>
    <child link="knee_r_servo_0"/>
    <origin rpy="0 0 1.5707963267948966" xyz="-.030 0 -.190"/>
  </joint>
  <link name="knee_r_servo_0">
    <visual>
      <origin rpy="0 0 0" xyz="0 0 0"/>
      <geometry>
        <mesh filename="package://tori_description/meshes/servo.stl" scale=".001 .001 .001"/>
      </geometry>
      <material name="Black"/>
      <color rgba="0.0 0.0 0.0 0.0"/>
    </visual>
    <collision>
      <origin rpy="0 0 0" xyz="0 0 0"/>
      <geometry>
        <mesh filename="package://tori_description/meshes/servo.stl" scale=".001 .001 .001"/>
        --&gt;
          
      </geometry>
    </collision>
    <inertial>
      <origin rpy="0 0 0" xyz="0 0 0"/>
      <mass value="0.064"/>
      <inertia ixx="8.106666e-06" ixy="0.0" ixz="0.0" iyy="4.967866e-06" iyz="0.0" izz="4.967866e-06"/>
    </inertial>
  </link>
  <joint name="knee_r_servo_1_joint" type="fixed">
    <parent link="thigh_r"/>
    <child link="knee_r_servo_1"/>
    <origin rpy="0 0 1.5707963267948966" xyz=".030 0 -.190"/>
  </joint>
  <link name="knee_r_servo_1">
    <visual>
      <origin rpy="0 0 0" xyz="0 0 0"/>
      <geometry>
        <mesh filename="package://tori_description/meshes/servo.stl" scale=".001 .001 .001"/>
      </geometry>
      <material name="Black"/>
      <color rgba="0.0 0.0 0.0 0.0"/>
    </visual>
    <collision>
      <origin rpy="0 0 0" xyz="0 0 0"/>
      <geometry>
        <mesh filename="package://tori_description/meshes/servo.stl" scale=".001 .001 .001"/>
        --&gt;
          
      </geometry>
    </collision>
    <inertial>
      <origin rpy="0 0 0" xyz="0 0 0"/>
      <mass value="0.064"/>
      <inertia ixx="8.106666e-06" ixy="0.0" ixz="0.0" iyy="4.967866e-06" iyz="0.0" izz="4.967866e-06"/>
    </inertial>
  </link>
  <joint name="knee_r" type="revolute">
    <parent link="thigh_r"/>
    <child link="calf_r"/>
    <origin rpy="0 0 0" xyz="0 0 -0.198"/>
    <axis xyz="1 0 0"/>
    <dynamics damping="0"/>
    <limit effort="3.92" lower="-1.57" upper="0" velocity="1.97"/>
  </joint>
  <link name="calf_r">
    <visual>
      <origin rpy="0 0 0" xyz="0 0 0"/>
      <geometry>
        <mesh filename="package://tori_description/meshes/calf_r.stl" scale=".001 .001 .001"/>
      </geometry>
      <material name="1.0 1.0 1.0 1.0"/>
    </visual>
    <collision>
      <origin rpy="0 0 0" xyz="0 0 0"/>
      <geometry>
        <mesh filename="package://tori_description/meshes/calf_r_collision.stl" scale=".001 .001 .001"/>
      </geometry>
    </collision>
    <inertial>
      <origin rpy="0 0 0" xyz="-.000004121 .007987968 -.128351074"/>
      <mass value="0.41"/>
      <inertia ixx="0.004194820608" ixy="-4.73618125e-07" ixz="-4.5179603125e-07" iyy="0.004509438976" iyz="6.2615448e-05" izz="0.003256164352"/>
    </inertial>
  </link>
  <joint name="ankle_servo_0_joint" type="fixed">
    <parent link="calf_r"/>
    <child link="ankle_servo_0"/>
    <origin rpy="0 0 1.5707963267948966" xyz="-.045 0 -.211"/>
  </joint>
  <link name="ankle_servo_0">
    <visual>
      <origin rpy="0 0 0" xyz="0 0 0"/>
      <geometry>
        <mesh filename="package://tori_description/meshes/servo.stl" scale=".001 .001 .001"/>
      </geometry>
      <material name="Black"/>
      <color rgba="0.0 0.0 0.0 0.0"/>
    </visual>
    <collision>
      <origin rpy="0 0 0" xyz="0 0 0"/>
      <geometry>
        <mesh filename="package://tori_description/meshes/servo.stl" scale=".001 .001 .001"/>
        --&gt;
          
      </geometry>
    </collision>
    <inertial>
      <origin rpy="0 0 0" xyz="0 0 0"/>
      <mass value="0.07"/>
      <inertia ixx="8.106666e-06" ixy="0.0" ixz="0.0" iyy="4.967866e-06" iyz="0.0" izz="4.967866e-06"/>
    </inertial>
  </link>
  <joint name="ankle_servo_1_joint" type="fixed">
    <parent link="calf_r"/>
    <child link="ankle_servo_1"/>
    <origin rpy="0 0 1.5707963267948966" xyz=".045 0 -.211"/>
  </joint>
  <link name="ankle_servo_1">
    <visual>
      <origin rpy="0 0 0" xyz="0 0 0"/>
      <geometry>
        <mesh filename="package://tori_description/meshes/servo.stl" scale=".001 .001 .001"/>
      </geometry>
      <material name="Black"/>
      <color rgba="0.0 0.0 0.0 0.0"/>
    </visual>
    <collision>
      <origin rpy="0 0 0" xyz="0 0 0"/>
      <geometry>
        <mesh filename="package://tori_description/meshes/servo.stl" scale=".001 .001 .001"/>
        --&gt;
          
      </geometry>
    </collision>
    <inertial>
      <origin rpy="0 0 0" xyz="0 0 0"/>
      <mass value="0.07"/>
      <inertia ixx="8.106666e-06" ixy="0.0" ixz="0.0" iyy="4.967866e-06" iyz="0.0" izz="4.967866e-06"/>
    </inertial>
  </link>
  <joint name="ankle_r_x" type="revolute">
    <parent link="calf_r"/>
    <child link="ankle_r"/>
    <origin rpy="0 0 0" xyz="0 0 -0.222"/>
    <axis xyz="1 0 0"/>
    <dynamics damping="0"/>
    <limit effort="3.92" lower="-0.52" upper="0.8" velocity="1.75"/>
  </joint>
  <link name="ankle_r">
    <collision>
      <origin rpy="0 0 0" xyz="0 0 0"/>
      <geometry>
        <mesh filename="package://tori_description/meshes/ankle_r_collision.stl" scale=".001 .001 .001"/>
      </geometry>
    </collision>
    <visual>
      <origin rpy="0 0 0" xyz="0 0 0"/>
      <geometry>
        <mesh filename="package://tori_description/meshes/ankle_r_collision.stl" scale=".001 .001 .001"/>
      </geometry>
      <material name="Black"/>
      <color rgba="0.0 0.0 0.0 0.0"/>
    </visual>
    <inertial>
      <origin rpy="0 0 0" xyz="-.000618945 .000017144 -.043992859"/>
      <mass value="0.058"/>
      <inertia ixx="0.000123806944" ixy="2.96732086e-10" ixz="1.84197671875e-07" iyy="0.000127575752" iyz="3.6397789062e-08" izz="0.00022416552"/>
    </inertial>
  </link>
  <joint name="foot_servo_0_joint" type="fixed">
    <parent link="foot_r"/>
    <child link="foot_servo_0"/>
    <origin rpy="0 0 0" xyz="0 .045 -.012"/>
  </joint>
  <link name="foot_servo_0">
    <visual>
      <origin rpy="0 0 0" xyz="0 0 0"/>
      <geometry>
        <mesh filename="package://tori_description/meshes/servo.stl" scale=".001 .001 .001"/>
      </geometry>
      <material name="Black"/>
      <color rgba="0.0 0.0 0.0 0.0"/>
    </visual>
    <collision>
      <origin rpy="0 0 0" xyz="0 0 -.05"/>
      <geometry>
        <mesh filename="package://tori_description/meshes/servo.stl" scale=".001 .001 .001"/>
        --&gt;
          
      </geometry>
    </collision>
    <inertial>
      <origin rpy="0 0 0" xyz="0 0 0"/>
      <mass value="0.07"/>
      <inertia ixx="8.106666e-06" ixy="0.0" ixz="0.0" iyy="4.967866e-06" iyz="0.0" izz="4.967866e-06"/>
    </inertial>
  </link>
  <joint name="foot_servo_1_joint" type="fixed">
    <parent link="foot_r"/>
    <child link="foot_servo_1"/>
    <origin rpy="0 0 0" xyz="0 -.045 -.012"/>
  </joint>
  <link name="foot_servo_1">
    <visual>
      <origin rpy="0 0 0" xyz="0 0 0"/>
      <geometry>
        <mesh filename="package://tori_description/meshes/servo.stl" scale=".001 .001 .001"/>
      </geometry>
      <material name="Black"/>
      <color rgba="0.0 0.0 0.0 0.0"/>
    </visual>
    <collision>
      <origin rpy="0 0 0" xyz="0 0 0"/>
      <geometry>
        <mesh filename="package://tori_description/meshes/servo.stl" scale=".001 .001 .001"/>
        --&gt;
          
      </geometry>
    </collision>
    <inertial>
      <origin rpy="0 0 0" xyz="0 0 0"/>
      <mass value="0.07"/>
      <inertia ixx="8.106666e-06" ixy="0.0" ixz="0.0" iyy="4.967866e-06" iyz="0.0" izz="4.967866e-06"/>
    </inertial>
  </link>
  <!--
      <joint name="${prefix}ball_joint_r" type="revolute">
        <parent link="${prefix}foot_r"/>
        <child link="${prefix}ball_r"/>
        <origin xyz="0 .1 -.02" rpy="0 0 0"/>
        <axis xyz="1 0 0"/>
        <dynamics damping="${damping}"/>
      <limit lower="${lower_limit_ball}" upper="${upper_limit_ball}" effort="${effort_ball}" velocity="${joint_velocity}"/>
    </joint>
      <link name="${prefix}ball_r">
        <collision>
          <origin xyz=".0 .025 0" rpy="0 0 0"/>
          <geometry>
            <box size="0.08 0.05 0.02"/>
          </geometry>
        </collision>
        <visual>
          <origin xyz=".0 .025 0" rpy="0 0 0"/>
          <geometry>
            <box size="0.08 0.05 0.02"/>
          </geometry>
          <material name="${Red}"/>
        </visual>
        <xacro:box_inertial height=".02" width="0.08" depth=".05" mass="${mass_ball}" pos=".0 .025 0" ang="0 0 0">
        </xacro:box_inertial>
      </link>-->
  <!-- LEFT LEG -->
  <joint name="hip_l_z" type="revolute">
    <parent link="pelvis"/>
    <child link="hip_l_z_x"/>
    <origin rpy="0 0 0" xyz="-0.1 0 0"/>
    <axis xyz="0 0 -1"/>
    <dynamics damping="0"/>
    <limit effort="3.92" lower="-0.78" upper="0.78" velocity="1.75"/>
  </joint>
  <link name="hip_l_z_x">
    <visual>
      <origin rpy="0 0 0" xyz="0 0 0"/>
      <geometry>
        <mesh filename="package://tori_description/meshes/hip_z_x_l.stl" scale=".001 .001 .001"/>
      </geometry>
      <material name="Black"/>
      <color rgba="0.0 0.0 0.0 0.0"/>
    </visual>
    <collision>
      <origin rpy="0 0 0" xyz="0 0 0"/>
      <geometry>
        <mesh filename="package://tori_description/meshes/hip_z_x_l.stl" scale=".001 .001 .001"/>
        --&gt;
          
      </geometry>
    </collision>
    <inertial>
      <origin rpy="0 0 0" xyz="-.017570456 -.00347991 -.040112427"/>
      <mass value="0.121"/>
      <inertia ixx="0.000555078912" ixy="2.3186852e-05" ixz="0.000124676192" iyy="0.000702113536" iyz="-7.1674168e-05" izz="0.000281483904"/>
    </inertial>
  </link>
  <joint name="hip_l_x_servo_0_joint" type="fixed">
    <parent link="hip_l_z_x"/>
    <child link="hip_l_x_servo_0"/>
    <origin rpy="0 0 1.5707963267948966" xyz="-.050 0 -.090"/>
  </joint>
  <link name="hip_l_x_servo_0">
    <visual>
      <origin rpy="0 0 0" xyz="0 0 0"/>
      <geometry>
        <mesh filename="package://tori_description/meshes/servo.stl" scale=".001 .001 .001"/>
      </geometry>
      <material name="Black"/>
      <color rgba="0.0 0.0 0.0 0.0"/>
    </visual>
    <collision>
      <origin rpy="0 0 0" xyz="0 0 0"/>
      <geometry>
        <mesh filename="package://tori_description/meshes/servo.stl" scale=".001 .001 .001"/>
        --&gt;
          
      </geometry>
    </collision>
    <inertial>
      <origin rpy="0 0 0" xyz="0 0 0"/>
      <mass value="0.07"/>
      <inertia ixx="8.106666e-06" ixy="0.0" ixz="0.0" iyy="4.967866e-06" iyz="0.0" izz="4.967866e-06"/>
    </inertial>
  </link>
  <joint name="hip_l_x_servo_1_joint" type="fixed">
    <parent link="hip_l_z_x"/>
    <child link="hip_l_x_servo_1"/>
    <origin rpy="0 0 1.5707963267948966" xyz=".040 0 -.090"/>
  </joint>
  <link name="hip_l_x_servo_1">
    <visual>
      <origin rpy="0 0 0" xyz="0 0 0"/>
      <geometry>
        <mesh filename="package://tori_description/meshes/servo.stl" scale=".001 .001 .001"/>
      </geometry>
      <material name="Black"/>
      <color rgba="0.0 0.0 0.0 0.0"/>
    </visual>
    <collision>
      <origin rpy="0 0 0" xyz="0 0 0"/>
      <geometry>
        <mesh filename="package://tori_description/meshes/servo.stl" scale=".001 .001 .001"/>
        --&gt;
          
      </geometry>
    </collision>
    <inertial>
      <origin rpy="0 0 0" xyz="0 0 0"/>
      <mass value="0.07"/>
      <inertia ixx="8.106666e-06" ixy="0.0" ixz="0.0" iyy="4.967866e-06" iyz="0.0" izz="4.967866e-06"/>
    </inertial>
  </link>
  <joint name="hip_l_x" type="revolute">
    <parent link="hip_l_z_x"/>
    <child link="hip_l_x_y"/>
    <origin rpy="0 0 0" xyz="0 0 -0.1"/>
    <axis xyz="1 0 0"/>
    <dynamics damping="0"/>
    <limit effort="3.92" lower="0" upper="0.8" velocity="1.75"/>
  </joint>
  <link name="hip_l_x_y">
    <visual>
      <origin rpy="0 0 0" xyz="0 0 0"/>
      <geometry>
        <mesh filename="package://tori_description/meshes/hip_x_y_l.stl" scale=".001 .001 .001"/>
      </geometry>
      <material name="Black"/>
      <color rgba="0.0 0.0 0.0 0.0"/>
    </visual>
    <collision>
      <origin rpy="0 0 0" xyz="0 0 0"/>
      <geometry>
        <mesh filename="package://tori_description/meshes/hip_x_y_l.stl" scale=".001 .001 .001"/>
        --&gt;
          
      </geometry>
    </collision>
    <inertial>
      <origin rpy="0 0 0" xyz="-.001901933 .000002684 -.019281031"/>
      <mass value="0.057"/>
      <inertia ixx="9.0316016e-05" ixy="2.1078759770000002e-09" ixz="-2.91498925e-06" iyy="0.000127007568" iyz="6.5668232420000005e-09" izz="0.000164438"/>
    </inertial>
  </link>
  <joint name="hip_l_y" type="revolute">
    <parent link="hip_l_x_y"/>
    <child link="thigh_l"/>
    <origin rpy="0 0 0" xyz="0 0 -0.035"/>
    <axis xyz="0 -1 0"/>
    <dynamics damping="0"/>
    <limit effort="3.92" lower="-0.52" upper="0.78" velocity="1.75"/>
  </joint>
  <link name="thigh_l">
    <visual>
      <origin rpy="0 0 0" xyz="0 0 0"/>
      <geometry>
        <mesh filename="package://tori_description/meshes/thigh_l.stl" scale=".001 .001 .001"/>
      </geometry>
      <material name="Black"/>
      <color rgba="0.0 0.0 0.0 0.0"/>
    </visual>
    <collision>
      <origin rpy="0 0 0" xyz="0 0 0"/>
      <geometry>
        <mesh filename="package://tori_description/meshes/thigh_l_collision.stl" scale=".001 .001 .001"/>
      </geometry>
    </collision>
    <inertial>
      <origin rpy="0 0 0" xyz=".002060390 .006943429 -.137976913"/>
      <mass value="0.343"/>
      <inertia ixx="0.002766745088" ixy="3.52151125e-07" ixz="-7.977528e-06" iyy="0.002732864512" iyz="0.00045015801599999997" izz="0.002102034688"/>
    </inertial>
  </link>
  <joint name="hip_l_y_servo_0_joint" type="fixed">
    <parent link="thigh_l"/>
    <child link="hip_l_y_servo_0"/>
    <origin rpy="0 0 0" xyz="0 .035 -.011"/>
  </joint>
  <link name="hip_l_y_servo_0">
    <visual>
      <origin rpy="0 0 0" xyz="0 0 0"/>
      <geometry>
        <mesh filename="package://tori_description/meshes/servo.stl" scale=".001 .001 .001"/>
      </geometry>
      <material name="Black"/>
      <color rgba="0.0 0.0 0.0 0.0"/>
    </visual>
    <collision>
      <origin rpy="0 0 0" xyz="0 0 0"/>
      <geometry>
        <mesh filename="package://tori_description/meshes/servo.stl" scale=".001 .001 .001"/>
        --&gt;
          
      </geometry>
    </collision>
    <inertial>
      <origin rpy="0 0 0" xyz="0 0 0"/>
      <mass value="0.07"/>
      <inertia ixx="8.106666e-06" ixy="0.0" ixz="0.0" iyy="4.967866e-06" iyz="0.0" izz="4.967866e-06"/>
    </inertial>
  </link>
  <joint name="hip_l_y_servo_1_joint" type="fixed">
    <parent link="thigh_l"/>
    <child link="hip_l_y_servo_1"/>
    <origin rpy="0 0 0" xyz="0 -.035 -.011"/>
  </joint>
  <link name="hip_l_y_servo_1">
    <visual>
      <origin rpy="0 0 0" xyz="0 0 0"/>
      <geometry>
        <mesh filename="package://tori_description/meshes/servo.stl" scale=".001 .001 .001"/>
      </geometry>
      <material name="Black"/>
      <color rgba="0.0 0.0 0.0 0.0"/>
    </visual>
    <collision>
      <origin rpy="0 0 0" xyz="0 0 0"/>
      <geometry>
        <mesh filename="package://tori_description/meshes/servo.stl" scale=".001 .001 .001"/>
        --&gt;
          
      </geometry>
    </collision>
    <inertial>
      <origin rpy="0 0 0" xyz="0 0 0"/>
      <mass value="0.07"/>
      <inertia ixx="8.106666e-06" ixy="0.0" ixz="0.0" iyy="4.967866e-06" iyz="0.0" izz="4.967866e-06"/>
    </inertial>
  </link>
  <joint name="knee_l_servo_0_joint" type="fixed">
    <parent link="thigh_l"/>
    <child link="knee_l_servo_0"/>
    <origin rpy="0 0 1.5707963267948966" xyz="-.030 0 -.190"/>
  </joint>
  <link name="knee_l_servo_0">
    <visual>
      <origin rpy="0 0 0" xyz="0 0 0"/>
      <geometry>
        <mesh filename="package://tori_description/meshes/servo.stl" scale=".001 .001 .001"/>
      </geometry>
      <material name="Black"/>
      <color rgba="0.0 0.0 0.0 0.0"/>
    </visual>
    <collision>
      <origin rpy="0 0 0" xyz="0 0 0"/>
      <geometry>
        <mesh filename="package://tori_description/meshes/servo.stl" scale=".001 .001 .001"/>
        --&gt;
          
      </geometry>
    </collision>
    <inertial>
      <origin rpy="0 0 0" xyz="0 0 0"/>
      <mass value="0.064"/>
      <inertia ixx="8.106666e-06" ixy="0.0" ixz="0.0" iyy="4.967866e-06" iyz="0.0" izz="4.967866e-06"/>
    </inertial>
  </link>
  <joint name="knee_l_servo_1_joint" type="fixed">
    <parent link="thigh_l"/>
    <child link="knee_l_servo_1"/>
    <origin rpy="0 0 1.5707963267948966" xyz=".030 0 -.190"/>
  </joint>
  <link name="knee_l_servo_1">
    <visual>
      <origin rpy="0 0 0" xyz="0 0 0"/>
      <geometry>
        <mesh filename="package://tori_description/meshes/servo.stl" scale=".001 .001 .001"/>
      </geometry>
      <material name="Black"/>
      <color rgba="0.0 0.0 0.0 0.0"/>
    </visual>
    <collision>
      <origin rpy="0 0 0" xyz="0 0 0"/>
      <geometry>
        <mesh filename="package://tori_description/meshes/servo.stl" scale=".001 .001 .001"/>
        --&gt;
          
      </geometry>
    </collision>
    <inertial>
      <origin rpy="0 0 0" xyz="0 0 0"/>
      <mass value="0.064"/>
      <inertia ixx="8.106666e-06" ixy="0.0" ixz="0.0" iyy="4.967866e-06" iyz="0.0" izz="4.967866e-06"/>
    </inertial>
  </link>
  <joint name="knee_l" type="revolute">
    <parent link="thigh_l"/>
    <child link="calf_l"/>
    <origin rpy="0 0 0" xyz="0 0 -0.198"/>
    <axis xyz="1 0 0"/>
    <dynamics damping="0"/>
    <limit effort="3.92" lower="-1.57" upper="0" velocity="1.97"/>
  </joint>
  <link name="calf_l">
    <visual>
      <origin rpy="0 0 0" xyz="0 0 0"/>
      <geometry>
        <mesh filename="package://tori_description/meshes/calf_l.stl" scale=".001 .001 .001"/>
      </geometry>
      <material name="1.0 1.0 1.0 1.0"/>
    </visual>
    <collision>
      <origin rpy="0 0 0" xyz="0 0 0"/>
      <geometry>
        <mesh filename="package://tori_description/meshes/calf_l_collision.stl" scale=".001 .001 .001"/>
      </geometry>
    </collision>
    <inertial>
      <origin rpy="0 0 0" xyz=".000008944 .001660231 -.123774109"/>
      <mass value="0.41"/>
      <inertia ixx="0.00419529856" ixy="4.3672153125e-07" ixz="9.741644375e-07" iyy="0.004510084608" iyz="6.263556799999999e-05" izz="0.003256341504"/>
    </inertial>
  </link>
  <joint name="ankle_l_servo_0_joint" type="fixed">
    <parent link="calf_l"/>
    <child link="ankle_l_servo_0"/>
    <origin rpy="0 0 1.5707963267948966" xyz="-.045 0 -.211"/>
  </joint>
  <link name="ankle_l_servo_0">
    <visual>
      <origin rpy="0 0 0" xyz="0 0 0"/>
      <geometry>
        <mesh filename="package://tori_description/meshes/servo.stl" scale=".001 .001 .001"/>
      </geometry>
      <material name="Black"/>
      <color rgba="0.0 0.0 0.0 0.0"/>
    </visual>
    <collision>
      <origin rpy="0 0 0" xyz="0 0 0"/>
      <geometry>
        <mesh filename="package://tori_description/meshes/servo.stl" scale=".001 .001 .001"/>
        --&gt;
          
      </geometry>
    </collision>
    <inertial>
      <origin rpy="0 0 0" xyz="0 0 0"/>
      <mass value="0.07"/>
      <inertia ixx="8.106666e-06" ixy="0.0" ixz="0.0" iyy="4.967866e-06" iyz="0.0" izz="4.967866e-06"/>
    </inertial>
  </link>
  <joint name="ankle_l_servo_1_joint" type="fixed">
    <parent link="calf_l"/>
    <child link="ankle_l_servo_1"/>
    <origin rpy="0 0 1.5707963267948966" xyz=".045 0 -.211"/>
  </joint>
  <link name="ankle_l_servo_1">
    <visual>
      <origin rpy="0 0 0" xyz="0 0 0"/>
      <geometry>
        <mesh filename="package://tori_description/meshes/servo.stl" scale=".001 .001 .001"/>
      </geometry>
      <material name="Black"/>
      <color rgba="0.0 0.0 0.0 0.0"/>
    </visual>
    <collision>
      <origin rpy="0 0 0" xyz="0 0 0"/>
      <geometry>
        <mesh filename="package://tori_description/meshes/servo.stl" scale=".001 .001 .001"/>
        --&gt;
          
      </geometry>
    </collision>
    <inertial>
      <origin rpy="0 0 0" xyz="0 0 0"/>
      <mass value="0.07"/>
      <inertia ixx="8.106666e-06" ixy="0.0" ixz="0.0" iyy="4.967866e-06" iyz="0.0" izz="4.967866e-06"/>
    </inertial>
  </link>
  <joint name="ankle_l_x" type="revolute">
    <parent link="calf_l"/>
    <child link="ankle_l"/>
    <origin rpy="0 0 0" xyz="0 0 -0.222"/>
    <axis xyz="1 0 0"/>
    <dynamics damping="0"/>
    <limit effort="3.92" lower="-0.52" upper="0.8" velocity="1.75"/>
  </joint>
  <link name="ankle_l">
    <visual>
      <origin rpy="0 0 0" xyz="0 0 0"/>
      <geometry>
        <mesh filename="package://tori_description/meshes/ankle_l_collision.stl" scale=".001 .001 .001"/>
      </geometry>
      <material name="Black"/>
      <color rgba="0.0 0.0 0.0 0.0"/>
    </visual>
    <collision>
      <origin rpy="0 0 0" xyz="0 0 0"/>
      <geometry>
        <mesh filename="package://tori_description/meshes/ankle_l_collision.stl" scale=".001 .001 .001"/>
      </geometry>
    </collision>
    <inertial>
      <origin rpy="0 0 0" xyz=".000628665 .000016178 -.043992519"/>
      <mass value="0.058"/>
      <inertia ixx="0.00012381117599999999" ixy="1.080197144e-09" ixz="-1.9812340625e-07" iyy="0.00012761047999999999" iyz="3.316434375e-08" izz="0.00022420292799999998"/>
    </inertial>
  </link>
  <joint name="ankle_l_y" type="revolute">
    <parent link="ankle_l"/>
    <child link="foot_l"/>
    <origin rpy="0 0 0" xyz="0 0 -0.095"/>
    <axis xyz="0 -1 0"/>
    <dynamics damping="0"/>
    <limit effort="3.92" lower="-0.52" upper="0.52" velocity="1.75"/>
  </joint>
  <link name="foot_l">
    <collision>
      <origin rpy="0 0 0" xyz="0 0 0"/>
      <geometry>
        <mesh filename="package://tori_description/meshes/foot_l_collision.stl" scale=".001 .001 .001"/>
        --&gt;
          
      </geometry>
      <!--<contact_coefficient mu="10"  resitution="1"  k_p="1000000"  k_d="100" />-->
    </collision>
    <visual>
      <origin rpy="0 0 0" xyz="0 0 0"/>
      <geometry>
        <mesh filename="package://tori_description/meshes/foot_l_collision.stl" scale=".001 .001 .001"/>
        --&gt;
          
      </geometry>
      <material name="1.0 0.0 0.0 1.0"/>
    </visual>
    <inertial>
      <origin rpy="0 0 0" xyz=".003465025 .004649493 -.042715496"/>
      <mass value="0.246"/>
      <inertia ixx="0.001278722816" ixy="-3.585326e-06" ixz="1.5627451e-05" iyy="0.0008087948159999999" iyz="-2.270335e-05" izz="0.001933839488"/>
    </inertial>
  </link>
  <gazebo reference="foot_l">
    <selfCollide>true</selfCollide>
    <maxContacts>10</maxContacts>
    <minDepth>0.00</minDepth>
    <maxVel>1.00</maxVel>
    <kp>1000000.0</kp>
    <kd>100.0</kd>
    <collision name="foot_l_collision">
      <geometry>
        <mesh filename="package://tori_description/meshes/foot_l_collision.stl" scale=".001 .001 .001"/>
        --&gt;
          
      </geometry>
      <surface>
        <!--<kp>1000000.0</kp>
            <kd>100.0</kd>
            <mu1>1.5</mu1>
            <mu2>1.5</mu2>
            <fdir1>1 0 0</fdir1>
            <maxVel>1.0</maxVel>
            <minDepth>0.00</minDepth>-->
        <friction>
          <ode>
            <mu>9.98500</mu>
            <mu2>9.98500</mu2>
            <fdir1>1.000000 0.000000 0.000000</fdir1>
            <slip1>0.000000</slip1>
            <slip2>0.000000</slip2>
            <!--<kp>1000000.0</kp>
                <kd>100.0</kd>-->
          </ode>
          <!--<contact>
                <poissons_ratio>0.5</poissons_ratio>
                <elastic_modulus>1e8</elastic_modulus>
              </contact>
              <mu>10.00</mu>
              <mu2>10.00</mu2>-->
          <torsional>
            <coefficient>500</coefficient>
            <use_patch_radius>true</use_patch_radius>
            <surface_radius>5</surface_radius>
            <patch_radius>1</patch_radius>
          </torsional>
        </friction>
      </surface>
    </collision>
  </gazebo>
  <joint name="ankle_r_y" type="revolute">
    <parent link="ankle_r"/>
    <child link="foot_r"/>
    <origin rpy="0 0 0" xyz="0 0 -0.095"/>
    <axis xyz="0 1 0"/>
    <dynamics damping="0"/>
    <limit effort="3.92" lower="-0.52" upper="0.52" velocity="1.75"/>
  </joint>
  <link name="foot_r">
    <visual>
      <origin rpy="0 0 0" xyz="0 0 0"/>
      <geometry>
        <mesh filename="package://tori_description/meshes/foot_r_collision.stl" scale=".001 .001 .001"/>
        --&gt;
          
      </geometry>
      <material name="1.0 0.0 0.0 1.0"/>
    </visual>
    <collision>
      <origin rpy="0 0 0" xyz="0 0 0"/>
      <geometry>
        <mesh filename="package://tori_description/meshes/foot_r_collision.stl" scale=".001 .001 .001"/>
        --&gt;
          
      </geometry>
      <!--<contact_coefficient mu="100"  resitution="0"  k_p="0"  k_d="0" />-->
    </collision>
    <inertial>
      <origin rpy="0 0 0" xyz="-.003453289 .004650488 -.042721497"/>
      <mass value="0.246"/>
      <inertia ixx="0.001278494208" ixy="3.57941875e-06" ixz="-1.5607733e-05" iyy="0.0008086602879999999" iyz="-2.2713808e-05" izz="0.001933690624"/>
    </inertial>
  </link>
  <gazebo reference="foot_r">
    <selfCollide>true</selfCollide>
    <maxContacts>10</maxContacts>
    <minDepth>0.00</minDepth>
    <maxVel>1.00</maxVel>
    <kp>1000000.0</kp>
    <kd>100.0</kd>
    <collision name="foot_r_collision">
      <geometry>
        <mesh filename="package://tori_description/meshes/foot_r_collision.stl" scale=".001 .001 .001"/>
        --&gt;
          
      </geometry>
      <surface>
        <!--<kp>1000000.0</kp>
            <kd>100.0</kd>
            <mu1>1.5</mu1>
            <mu2>1.5</mu2>
            <fdir1>1 0 0</fdir1>
            <maxVel>1.0</maxVel>
            <minDepth>0.00</minDepth>-->
        <friction>
          <ode>
            <mu>9.98500</mu>
            <mu2>9.98500</mu2>
            <fdir1>1.000000 0.000000 0.000000</fdir1>
            <slip1>0.000000</slip1>
            <slip2>0.000000</slip2>
            <!--<kp>1000000.0</kp>
                <kd>100.0</kd>-->
          </ode>
          <!--<contact>
                <poissons_ratio>0.5</poissons_ratio>
                <elastic_modulus>1e8</elastic_modulus>
              </contact>
              <mu>10.00</mu>
              <mu2>10.00</mu2>-->
          <torsional>
            <coefficient>500</coefficient>
            <use_patch_radius>true</use_patch_radius>
            <surface_radius>5</surface_radius>
            <patch_radius>1</patch_radius>
          </torsional>
        </friction>
      </surface>
    </collision>
  </gazebo>
  <joint name="foot_l_servo_0_joint" type="fixed">
    <parent link="foot_l"/>
    <child link="foot_l_servo_0"/>
    <origin rpy="0 0 0" xyz="0 .045 -.012"/>
  </joint>
  <link name="foot_l_servo_0">
    <visual>
      <origin rpy="0 0 0" xyz="0 0 0"/>
      <geometry>
        <mesh filename="package://tori_description/meshes/servo.stl" scale=".001 .001 .001"/>
      </geometry>
      <material name="Black"/>
      <color rgba="0.0 0.0 0.0 0.0"/>
    </visual>
    <collision>
      <origin rpy="0 0 0" xyz="0 0 0"/>
      <geometry>
        <mesh filename="package://tori_description/meshes/servo.stl" scale=".001 .001 .001"/>
        --&gt;
          
      </geometry>
    </collision>
    <inertial>
      <origin rpy="0 0 0" xyz="0 0 0"/>
      <mass value="0.07"/>
      <inertia ixx="8.106666e-06" ixy="0.0" ixz="0.0" iyy="4.967866e-06" iyz="0.0" izz="4.967866e-06"/>
    </inertial>
  </link>
  <joint name="foot_l_servo_1_joint" type="fixed">
    <parent link="foot_l"/>
    <child link="foot_l_servo_1"/>
    <origin rpy="0 0 0" xyz="0 -.045 -.012"/>
  </joint>
  <link name="foot_l_servo_1">
    <collision>
      <origin rpy="0 0 0" xyz="0 0 0"/>
      <geometry>
        <mesh filename="package://tori_description/meshes/servo.stl" scale=".001 .001 .001"/>
        --&gt;
          
      </geometry>
    </collision>
    <visual>
      <origin rpy="0 0 0" xyz="0 0 0"/>
      <geometry>
        <mesh filename="package://tori_description/meshes/servo.stl" scale=".001 .001 .001"/>
      </geometry>
      <material name="Black"/>
      <color rgba="0.0 0.0 0.0 0.0"/>
    </visual>
    <inertial>
      <origin rpy="0 0 0" xyz="0 0 0"/>
      <mass value="0.07"/>
      <inertia ixx="8.106666e-06" ixy="0.0" ixz="0.0" iyy="4.967866e-06" iyz="0.0" izz="4.967866e-06"/>
    </inertial>
  </link>
  <!--
      <joint name="${prefix}ball_joint_l" type="revolute">
        <parent link="${prefix}foot_l"/>
        <child link="${prefix}ball_l"/>
        <origin xyz="0 .1 -.02" rpy="0 0 0"/>
        <axis xyz="1 0 0"/>
        <dynamics damping="${damping}"/>
        <limit lower="${lower_limit_ball}" upper="${upper_limit_ball}" effort="${effort_ball}" velocity="${joint_velocity}"/>
    </joint>
      <link name="${prefix}ball_l">
        <collision>
          <origin xyz="0 .025 0" rpy="0 0 0"/>
          <geometry>
            <box size="0.08 0.05 0.02"/>
          </geometry>
        </collision>
        <visual>
          <origin xyz="0 .025 0" rpy="0 0 0"/>
          <geometry>
      <box size="0.08 0.05 0.02"/>
          </geometry>
          <material name="${Red}"/>
        </visual>
        <xacro:box_inertial height=".02" width=".11" depth=".08" mass="${mass_ball}" pos="0 .025 0" ang="0 0 0">
        </xacro:box_inertial>
      </link>-->
  <!--
    <transmission name="shoulder_l_x_trans">
      <type>transmission_interface/SimpleTransmission</type>
      <joint name="shoulder_l_x">
        <hardwareInterface>${hw_interface}</hardwareInterface>
      </joint>
      <actuator name="shoulder_l_x_motor">
        <mechanicalReduction>1</mechanicalReduction>
      </actuator>
    </transmission>

    <transmission name="shoulder_l_y_trans">
      <type>transmission_interface/SimpleTransmission</type>
      <joint name="shoulder_l_y">
        <hardwareInterface>${hw_interface}</hardwareInterface>
      </joint>
      <actuator name="shoulder_l_y_motor">
        <mechanicalReduction>1</mechanicalReduction>
      </actuator>
    </transmission>

    <transmission name="${prefix}shoulder_l_z_trans">
      <type>transmission_interface/SimpleTransmission</type>
      <joint name="${prefix}shoulder_l_z">
        <hardwareInterface>${hw_interface}</hardwareInterface>
      </joint>
      <actuator name="${prefix}shoulder_l_z_motor">
        <mechanicalReduction>1</mechanicalReduction>
      </actuator>
    </transmission>

    <transmission name="${prefix}elbow_l_z_trans">
      <type>transmission_interface/SimpleTransmission</type>
      <joint name="${prefix}elbow_l_z">
        <hardwareInterface>${hw_interface}</hardwareInterface>
      </joint>
      <actuator name="${prefix}elbow_l_z_motor">
        <mechanicalReduction>1</mechanicalReduction>
      </actuator>
    </transmission>

    <transmission name="${prefix}elbow_l_x_trans">
      <type>transmission_interface/SimpleTransmission</type>
      <joint name="${prefix}elbow_l_x">
        <hardwareInterface>${hw_interface}</hardwareInterface>
      </joint>
      <actuator name="${prefix}elbow_l_x_motor">
        <mechanicalReduction>1</mechanicalReduction>
      </actuator>
    </transmission>

    <transmission name="${prefix}wrist_l_z_trans">
      <type>transmission_interface/SimpleTransmission</type>
      <joint name="${prefix}wrist_l_z">
        <hardwareInterface>${hw_interface}</hardwareInterface>
      </joint>
      <actuator name="${prefix}wrist_l_z_motor">
        <mechanicalReduction>1</mechanicalReduction>
      </actuator>
    </transmission>

    <transmission name="${prefix}wrist_l_y_trans">
      <type>transmission_interface/SimpleTransmission</type>
      <joint name="${prefix}wrist_l_y">
        <hardwareInterface>${hw_interface}</hardwareInterface>
      </joint>
      <actuator name="${prefix}wrist_l_y_motor">
        <mechanicalReduction>1</mechanicalReduction>
      </actuator>
    </transmission>

    <transmission name="${prefix}shoulder_r_x_trans">
      <type>transmission_interface/SimpleTransmission</type>
      <joint name="${prefix}shoulder_r_x">
        <hardwareInterface>${hw_interface}</hardwareInterface>
      </joint>
      <actuator name="${prefix}shoulder_r_x_motor">
        <mechanicalReduction>1</mechanicalReduction>
      </actuator>
    </transmission>

    <transmission name="${prefix}shoulder_r_y_trans">
      <type>transmission_interface/SimpleTransmission</type>
      <joint name="${prefix}shoulder_r_y">
        <hardwareInterface>${hw_interface}</hardwareInterface>
      </joint>
      <actuator name="${prefix}shoulder_r_y_motor">
        <mechanicalReduction>1</mechanicalReduction>
      </actuator>
    </transmission>

    <transmission name="${prefix}shoulder_r_z_trans">
      <type>transmission_interface/SimpleTransmission</type>
      <joint name="${prefix}shoulder_r_z">
        <hardwareInterface>${hw_interface}</hardwareInterface>
      </joint>
      <actuator name="${prefix}shoulder_r_z_motor">
        <mechanicalReduction>1</mechanicalReduction>
      </actuator>
    </transmission>

    <transmission name="${prefix}elbow_r_z_trans">
      <type>transmission_interface/SimpleTransmission</type>
      <joint name="${prefix}elbow_r_z">
        <hardwareInterface>${hw_interface}</hardwareInterface>
      </joint>
      <actuator name="${prefix}elbow_r_z_motor">
        <mechanicalReduction>1</mechanicalReduction>
      </actuator>
    </transmission>

    <transmission name="${prefix}elbow_r_x_trans">
      <type>transmission_interface/SimpleTransmission</type>
      <joint name="${prefix}elbow_r_x">
        <hardwareInterface>${hw_interface}</hardwareInterface>
      </joint>
      <actuator name="${prefix}elbow_r_x_motor">
        <mechanicalReduction>1</mechanicalReduction>
      </actuator>
    </transmission>

    <transmission name="${prefix}wrist_r_z_trans">
      <type>transmission_interface/SimpleTransmission</type>
      <joint name="${prefix}wrist_r_z">
        <hardwareInterface>${hw_interface}</hardwareInterface>
      </joint>
      <actuator name="${prefix}wrist_r_z_motor">
        <mechanicalReduction>1</mechanicalReduction>
      </actuator>
    </transmission>

    <transmission name="${prefix}wrist_r_y_trans">
      <type>transmission_interface/SimpleTransmission</type>
      <joint name="${prefix}wrist_r_y">
        <hardwareInterface>${hw_interface}</hardwareInterface>
      </joint>
      <actuator name="${prefix}wrist_r_y_motor">
        <mechanicalReduction>1</mechanicalReduction>
      </actuator>
    </transmission>
-->
  <transmission name="hip_l_x_trans">
    <type>transmission_interface/SimpleTransmission</type>
    <joint name="hip_l_x">
      <hardwareInterface>hardware_interface/PositionJointInterface</hardwareInterface>
    </joint>
    <actuator name="hip_l_x_motor">
      <mechanicalReduction>1</mechanicalReduction>
    </actuator>
  </transmission>
  <transmission name="hip_l_y_trans">
    <type>transmission_interface/SimpleTransmission</type>
    <joint name="hip_l_y">
      <hardwareInterface>hardware_interface/PositionJointInterface</hardwareInterface>
    </joint>
    <actuator name="hip_l_y_motor">
      <mechanicalReduction>1</mechanicalReduction>
    </actuator>
  </transmission>
  <transmission name="hip_l_z_trans">
    <type>transmission_interface/SimpleTransmission</type>
    <joint name="hip_l_z">
      <hardwareInterface>hardware_interface/PositionJointInterface</hardwareInterface>
    </joint>
    <actuator name="hip_l_z_motor">
      <mechanicalReduction>1</mechanicalReduction>
    </actuator>
  </transmission>
  <transmission name="knee_l_trans">
    <type>transmission_interface/SimpleTransmission</type>
    <joint name="knee_l">
      <hardwareInterface>hardware_interface/PositionJointInterface</hardwareInterface>
    </joint>
    <actuator name="knee_l_motor">
      <mechanicalReduction>1</mechanicalReduction>
    </actuator>
  </transmission>
  <transmission name="ankle_l_x_trans">
    <type>transmission_interface/SimpleTransmission</type>
    <joint name="ankle_l_x">
      <hardwareInterface>hardware_interface/PositionJointInterface</hardwareInterface>
    </joint>
    <actuator name="ankle_l_x_motor">
      <mechanicalReduction>1</mechanicalReduction>
    </actuator>
  </transmission>
  <transmission name="ankle_l_y_trans">
    <type>transmission_interface/SimpleTransmission</type>
    <joint name="ankle_l_y">
      <hardwareInterface>hardware_interface/PositionJointInterface</hardwareInterface>
    </joint>
    <actuator name="ankle_l_y_motor">
      <mechanicalReduction>1</mechanicalReduction>
    </actuator>
  </transmission>
  <transmission name="hip_r_x_trans">
    <type>transmission_interface/SimpleTransmission</type>
    <joint name="hip_r_x">
      <hardwareInterface>hardware_interface/PositionJointInterface</hardwareInterface>
    </joint>
    <actuator name="hip_r_x_motor">
      <mechanicalReduction>1</mechanicalReduction>
    </actuator>
  </transmission>
  <transmission name="hip_r_y_trans">
    <type>transmission_interface/SimpleTransmission</type>
    <joint name="hip_r_y">
      <hardwareInterface>hardware_interface/PositionJointInterface</hardwareInterface>
    </joint>
    <actuator name="hip_r_y_motor">
      <mechanicalReduction>1</mechanicalReduction>
    </actuator>
  </transmission>
  <transmission name="hip_r_z_trans">
    <type>transmission_interface/SimpleTransmission</type>
    <joint name="hip_r_z">
      <hardwareInterface>hardware_interface/PositionJointInterface</hardwareInterface>
    </joint>
    <actuator name="hip_r_z_motor">
      <mechanicalReduction>1</mechanicalReduction>
    </actuator>
  </transmission>
  <transmission name="knee_r_trans">
    <type>transmission_interface/SimpleTransmission</type>
    <joint name="knee_r">
      <hardwareInterface>hardware_interface/PositionJointInterface</hardwareInterface>
    </joint>
    <actuator name="knee_r_motor">
      <mechanicalReduction>1</mechanicalReduction>
    </actuator>
  </transmission>
  <transmission name="ankle_r_x_trans">
    <type>transmission_interface/SimpleTransmission</type>
    <joint name="ankle_r_x">
      <hardwareInterface>hardware_interface/PositionJointInterface</hardwareInterface>
    </joint>
    <actuator name="ankle_r_x_motor">
      <mechanicalReduction>1</mechanicalReduction>
    </actuator>
  </transmission>
  <transmission name="ankle_r_y_trans">
    <type>transmission_interface/SimpleTransmission</type>
    <joint name="ankle_r_y">
      <hardwareInterface>hardware_interface/PositionJointInterface</hardwareInterface>
    </joint>
    <actuator name="ankle_r_y_motor">
      <mechanicalReduction>1</mechanicalReduction>
    </actuator>
  </transmission>
  <transmission name="spine_x_trans">
    <type>transmission_interface/SimpleTransmission</type>
    <joint name="spine_x">
      <hardwareInterface>hardware_interface/PositionJointInterface</hardwareInterface>
    </joint>
    <actuator name="spine_x_motor">
      <mechanicalReduction>1</mechanicalReduction>
    </actuator>
  </transmission>
  <transmission name="spine_y_trans">
    <type>transmission_interface/SimpleTransmission</type>
    <joint name="spine_y">
      <hardwareInterface>hardware_interface/PositionJointInterface</hardwareInterface>
    </joint>
    <actuator name="spine_y_motor">
      <mechanicalReduction>1</mechanicalReduction>
    </actuator>
  </transmission>
  <transmission name="spine_z_trans">
    <type>transmission_interface/SimpleTransmission</type>
    <joint name="spine_z">
      <hardwareInterface>hardware_interface/PositionJointInterface</hardwareInterface>
    </joint>
    <actuator name="spine_z_motor">
      <mechanicalReduction>1</mechanicalReduction>
    </actuator>
  </transmission>
  <!--<transmission name="${prefix}ball_joint_l_trans">
      <type>transmission_interface/SimpleTransmission</type>
      <joint name="${prefix}ball_joint_l">
        <hardwareInterface>${hw_interface}</hardwareInterface>
      </joint>
      <actuator name="${prefix}ball_joint_l_motor">
        <mechanicalReduction>1</mechanicalReduction>
      </actuator>
    </transmission>

    <transmission name="${prefix}ball_joint_r_trans">
      <type>transmission_interface/SimpleTransmission</type>
      <joint name="${prefix}ball_joint_r">
        <hardwareInterface>${hw_interface}</hardwareInterface>
      </joint>
      <actuator name="${prefix}ball_joint_r_motor">
        <mechanicalReduction>1</mechanicalReduction>
      </actuator>
    </transmission>-->
  <gazebo reference="pelvis">
    <selfCollide>1</selfCollide>
    <implicitSpringDamper>True</implicitSpringDamper>
  </gazebo>
  <!--
    <gazebo reference="shoulder_l0">
      <selfCollide>False</selfCollide>
      <implicitSpringDamper>True</implicitSpringDamper>
    </gazebo>

    <gazebo reference="shoulder_l1">
      <selfCollide>False</selfCollide>
      <implicitSpringDamper>True</implicitSpringDamper>
    </gazebo>

    <gazebo reference="arm_l">
      <selfCollide>True</selfCollide>
    </gazebo>

    <gazebo reference="forearm_l">
      <selfCollide>False</selfCollide>
    </gazebo>
    <gazebo reference="wrist_l0">
      <selfCollide>True</selfCollide>
    </gazebo>
    <gazebo reference="wrist_l1">
      <selfCollide>False</selfCollide>
    </gazebo>
    <gazebo reference="hand_l">
      <selfCollide>True</selfCollide>
    </gazebo>

    <gazebo reference="${prefix}shoulder_r0">
      <selfCollide>False</selfCollide>
    </gazebo>
    <gazebo reference="${prefix}shoulder_r1">
      <selfCollide>False</selfCollide>
    </gazebo>
    <gazebo reference="${prefix}arm_r">
      <selfCollide>true</selfCollide>
    </gazebo>
    <gazebo reference="${prefix}forearm_r">
      <selfCollide>False</selfCollide>
    </gazebo>
    <gazebo reference="${prefix}wrist_r0">
      <selfCollide>true</selfCollide>
    </gazebo>
    <gazebo reference="${prefix}wrist_r1">
      <selfCollide>False</selfCollide>
    </gazebo>
    <gazebo reference="${prefix}hand_r">
      <selfCollide>true</selfCollide>
    </gazebo>
-->
  <gazebo reference="hip_l_z_x">
    <selfCollide>true</selfCollide>
  </gazebo>
  <gazebo reference="hip_l_x_y">
    <selfCollide>true</selfCollide>
  </gazebo>
  <gazebo reference="thigh_l">
    <selfCollide>true</selfCollide>
  </gazebo>
  <gazebo reference="shin_l">
    <selfCollide>true</selfCollide>
  </gazebo>
  <gazebo reference="ankle_l">
    <selfCollide>true</selfCollide>
  </gazebo>
  <gazebo reference="hip_r_z_x">
    <selfCollide>true</selfCollide>
  </gazebo>
  <gazebo reference="hip_r_x_y">
    <selfCollide>true</selfCollide>
  </gazebo>
  <gazebo reference="thigh_r">
    <selfCollide>true</selfCollide>
  </gazebo>
  <gazebo reference="shin_r">
    <selfCollide>true</selfCollide>
  </gazebo>
  <gazebo reference="ankle_r">
    <selfCollide>true</selfCollide>
  </gazebo>
  <gazebo reference="torso_lower">
    <selfCollide>1</selfCollide>
    <implicitSpringDamper>True</implicitSpringDamper>
  </gazebo>
  <gazebo reference="torso_mid">
    <selfCollide>1</selfCollide>
    <implicitSpringDamper>True</implicitSpringDamper>
  </gazebo>
  <gazebo reference="torso_upper">
    <selfCollide>True</selfCollide>
    <implicitSpringDamper>True</implicitSpringDamper>
  </gazebo>
  <!--  <link name="world" />

  <joint name="world_joint" type="fixed">
    <parent link="world" />
    <child link = "base_link" />
    <origin xyz="0.0 0.0 0.0" rpy="0.0 0.0 0.0" />
  </joint>
-->
</robot>

